Workbook

Sheet OCUPAÇÃO VEICULOS Att Fev 26
A1: ATUALIZAÇÃO QUANDO HOUVER ALTERAÇÃO
A2: ROTA | B2: VEÍCULO | C2: CAPACIDADE | D2: OCUPAÇÃO UTILIZADA | E2: VAGAS DISPONIVEIS | F2: % OCUPAÇÃO DISPONÍVEL | G2: TEMPO DE ROTA | H2: DISTÂNCIA IDA E VOLTA (KM) | I2: HORÁRIO DE CHEGADA FÁBRICA | J2: HORÁRIO SAÍDA FÁBRICA
C3: 1ºTURNO
A4: 1 | B4: {=_xlfn.IFS(C4=15,"VAN",C4=4,"CARRO PEQUENO",C4=6,"SPIN")} -> CARRO PEQUENO | C4: 4 | D4: 4 | E4: =C4-D4 -> 0 | F4: =E4/C4 -> 0 | G4: 0.024305556 | H4: 42 | I4: 0.23958333 | J4: 0.60416667
A5: 2 | B5: {=_xlfn.IFS(C5=15,"VAN",C5=4,"CARRO PEQUENO",C5=6,"SPIN")} -> CARRO PEQUENO | C5: 4 | D5: 1 | E5: =C5-D5 -> 3 | F5: =E5/C5 -> 0.75 | G5: 0.03125 | H5: 84 | I5: 0.23958333 | J5: 0.60416667
A6: 3 | B6: {=_xlfn.IFS(C6=15,"VAN",C6=4,"CARRO PEQUENO",C6=6,"SPIN")} -> VAN | C6: 15 | D6: 7 | E6: =C6-D6 -> 8 | F6: =E6/C6 -> 0.53333333 | G6: 0.046527778 | H6: 90 | I6: 0.23958333 | J6: 0.60416667
A7: 4 | B7: {=_xlfn.IFS(C7=15,"VAN",C7=4,"CARRO PEQUENO",C7=6,"SPIN")} -> VAN | C7: 15 | D7: 7 | E7: =C7-D7 -> 8 | F7: =E7/C7 -> 0.53333333 | G7: 0.052083333 | H7: 100 | I7: 0.23958333 | J7: 0.60416667
A8: 5 | B8: {=_xlfn.IFS(C8=15,"VAN",C8=4,"CARRO PEQUENO",C8=6,"SPIN")} -> VAN | C8: 15 | D8: 8 | E8: =C8-D8 -> 7 | F8: =E8/C8 -> 0.46666667 | G8: 0.041666667 | H8: 104 | I8: 0.23958333 | J8: 0.60416667
A9: 6 | B9: {=_xlfn.IFS(C9=15,"VAN",C9=4,"CARRO PEQUENO",C9=6,"SPIN")} -> VAN | C9: 15 | D9: 10 | E9: =C9-D9 -> 5 | F9: =E9/C9 -> 0.33333333 | G9: 0.052083333 | H9: 118 | I9: 0.23958333 | J9: 0.60416667
A10: 7 | B10: {=_xlfn.IFS(C10=15,"VAN",C10=4,"CARRO PEQUENO",C10=6,"SPIN")} -> CARRO PEQUENO | C10: 4 | D10: 3 | E10: =C10-D10 -> 1 | F10: =E10/C10 -> 0.25 | G10: 0.03125 | H10: 88 | I10: 0.23958333 | J10: 0.60416667
A11: 8 | B11: {=_xlfn.IFS(C11=15,"VAN",C11=4,"CARRO PEQUENO",C11=6,"SPIN")} -> VAN | C11: 15 | D11: 11 | E11: =C11-D11 -> 4 | F11: =E11/C11 -> 0.26666667 | G11: 0.055555556 | H11: 110 | I11: 0.23958333 | J11: 0.60416667
A12: 9 | B12: {=_xlfn.IFS(C12=15,"VAN",C12=4,"CARRO PEQUENO",C12=6,"SPIN")} -> CARRO PEQUENO | C12: 4 | D12: 2 | E12: =C12-D12 -> 2 | F12: =E12/C12 -> 0.5 | G12: 0.025694444 | H12: 88 | I12: 0.23958333 | J12: 0.60416667
A13: 10 | B13: {=_xlfn.IFS(C13=15,"VAN",C13=4,"CARRO PEQUENO",C13=6,"SPIN")} -> CARRO PEQUENO | C13: 4 | D13: 3 | E13: =C13-D13 -> 1 | F13: =E13/C13 -> 0.25 | G13: 0.052083333 | H13: 80 | I13: 0.23958333 | J13: 0.60416667
A14: TOTAL | C14: =SUM(C4:C13) -> 95 | D14: =SUM(D4:D13) -> 56 | E14: =SUM(E4:E13) -> 39 | F14: =E14/C14 -> 0.41052632 | G14: =AVERAGE(G4:G13) -> 0.04125 | H14: =SUM(H4:H13) -> 904
A16: ROTA | B16: VEÍCULO | C16: CAPACIDADE | D16: OCUPAÇÃO UTILIZADA | E16: VAGAS DISPONIVEIS | F16: % OCUPAÇÃO DISPONÍVEL | G16: TEMPO DE ROTA | H16: DISTÂNCIA IDA E VOLTA (KM) | I16: HORÁRIO DE CHEGADA FÁBRICA | J16: HORÁRIO SAÍDA FÁBRICA
C17: ADM
A18: 1 | B18: {=_xlfn.IFS(C18=15,"VAN",C18=4,"CARRO PEQUENO",C18=6,"SPIN")} -> CARRO PEQUENO | C18: 4 | D18: 4 | E18: =C18-D18 -> 0 | F18: =E18/C18 -> 0 | G18: 0.03125 | H18: 56 | I18: 0.30208333 | J18: 0.72083333
A19: 2 | B19: {=_xlfn.IFS(C19=15,"VAN",C19=4,"CARRO PEQUENO",C19=6,"SPIN")} -> CARRO PEQUENO | C19: 4 | D19: 4 | E19: =C19-D19 -> 0 | F19: =E19/C19 -> 0 | G19: 0.03125 | H19: 90 | I19: 0.30208333 | J19: 0.72083333
A20: 3 | B20: {=_xlfn.IFS(C20=15,"VAN",C20=4,"CARRO PEQUENO",C20=6,"SPIN")} -> CARRO PEQUENO | C20: 4 | D20: 3 | E20: =C20-D20 -> 1 | F20: =E20/C20 -> 0.25 | G20: 0.034722222 | H20: 62 | I20: 0.30208333 | J20: 0.72083333
A21: 4 | B21: {=_xlfn.IFS(C21=15,"VAN",C21=4,"CARRO PEQUENO",C21=6,"SPIN")} -> CARRO PEQUENO | C21: 4 | D21: 3 | E21: =C21-D21 -> 1 | F21: =E21/C21 -> 0.25 | G21: 0.022916667 | H21: 60 | I21: 0.30208333 | J21: 0.72083333
A22: 5 | B22: {=_xlfn.IFS(C22=15,"VAN",C22=4,"CARRO PEQUENO",C22=6,"SPIN")} -> CARRO PEQUENO | C22: 4 | D22: 4 | E22: =C22-D22 -> 0 | F22: =E22/C22 -> 0 | G22: 0.038194444 | H22: 64 | I22: 0.30208333 | J22: 0.72083333
A23: 6 | B23: {=_xlfn.IFS(C23=15,"VAN",C23=4,"CARRO PEQUENO",C23=6,"SPIN")} -> CARRO PEQUENO | C23: 4 | D23: 1 | E23: =C23-D23 -> 3 | F23: =E23/C23 -> 0.75 | G23: 0.024305556 | H23: 84 | I23: 0.30208333 | J23: 0.72083333
A24: 7 | B24: {=_xlfn.IFS(C24=15,"VAN",C24=4,"CARRO PEQUENO",C24=6,"SPIN")} -> CARRO PEQUENO | C24: 4 | D24: 2 | E24: =C24-D24 -> 2 | F24: =E24/C24 -> 0.5 | G24: 0.0069444444 | H24: 30 | I24: 0.30208333 | J24: 0.72083333
A25: 8 | B25: {=_xlfn.IFS(C25=15,"VAN",C25=4,"CARRO PEQUENO",C25=6,"SPIN")} -> CARRO PEQUENO | C25: 4 | D25: 2 | E25: =C25-D25 -> 2 | F25: =E25/C25 -> 0.5 | G25: 0.017361111 | H25: 66 | I25: 0.30208333 | J25: 0.72083333
A26: TOTAL | C26: =SUM(C18:C25) -> 32 | D26: =SUM(D18:D25) -> 23 | E26: =SUM(E18:E25) -> 9 | F26: =E26/C26 -> 0.28125 | G26: =AVERAGE(G18:G25) -> 0.025868056 | H26: =SUM(H18:H25) -> 512
A28: ROTA | B28: VEÍCULO | C28: CAPACIDADE | D28: OCUPAÇÃO UTILIZADA | E28: VAGAS DISPONIVEIS | F28: % OCUPAÇÃO DISPONÍVEL | G28: TEMPO DE ROTA | H28: DISTÂNCIA IDA E VOLTA (KM) | I28: HORÁRIO DE CHEGADA FÁBRICA | J28: HORÁRIO SAÍDA FÁBRICA
C29: 2° TURNO
A30: 1 | B30: {=_xlfn.IFS(C30=15,"VAN",C30=4,"CARRO PEQUENO",C30=6,"SPIN")} -> VAN | C30: 15 | D30: 8 | E30: =C30-D30 -> 7 | F30: =E30/C30 -> 0.46666667 | G30: 0.048611111 | H30: 112 | I30: 0.58680556 | J30: 0.94791667
A31: 2 | B31: {=_xlfn.IFS(C31=15,"VAN",C31=4,"CARRO PEQUENO",C31=6,"SPIN")} -> VAN | C31: 15 | D31: 8 | E31: =C31-D31 -> 7 | F31: =E31/C31 -> 0.46666667 | G31: 0.052083333 | H31: 100 | I31: 0.58680556 | J31: 0.94791667
A32: 3 | B32: {=_xlfn.IFS(C32=15,"VAN",C32=4,"CARRO PEQUENO",C32=6,"SPIN")} -> VAN | C32: 15 | D32: 6 | E32: =C32-D32 -> 9 | F32: =E32/C32 -> 0.6 | G32: 0.047916667 | H32: 82 | I32: 0.58680556 | J32: 0.94791667
A33: 4 | B33: {=_xlfn.IFS(C33=15,"VAN",C33=4,"CARRO PEQUENO",C33=6,"SPIN")} -> SPIN | C33: 6 | D33: 5 | E33: =C33-D33 -> 1 | F33: =E33/C33 -> 0.16666667 | G33: 0.04375 | H33: 100 | I33: 0.58680556 | J33: 0.94791667
A34: 5 | B34: {=_xlfn.IFS(C34=15,"VAN",C34=4,"CARRO PEQUENO",C34=6,"SPIN")} -> SPIN | C34: 6 | D34: 5 | E34: =C34-D34 -> 1 | F34: =E34/C34 -> 0.16666667 | G34: 0.045138889 | H34: 90 | I34: 0.58680556 | J34: 0.94791667
A35: TOTAL | C35: =SUM(C30:C34) -> 57 | D35: =SUM(D30:D34) -> 32 | E35: =SUM(E30:E34) -> 25 | F35: =E35/C35 -> 0.43859649 | G35: =AVERAGE(G30:G34) -> 0.0475 | H35: =SUM(H30:H34) -> 484
A37: ROTA | B37: VEÍCULO | C37: CAPACIDADE | D37: OCUPAÇÃO UTILIZADA | E37: VAGAS DISPONIVEIS | F37: % OCUPAÇÃO DISPONÍVEL | G37: TEMPO DE ROTA | H37: DISTÂNCIA IDA E VOLTA (KM) | I37: HORÁRIO CHEGADA FÁBRICA | J37: HORÁRIO SAÍDA FÁBRICA
C38: 3° TURNO
A39: 1 | B39: {=_xlfn.IFS(C39=15,"VAN",C39=4,"CARRO PEQUENO",C39=6,"SPIN")} -> VAN | C39: 15 | D39: 9 | E39: =C39-D39 -> 6 | F39: =E39/C39 -> 0.4 | G39: 0.03125 | H39: 108 | I39: 0.93055556 | J39: 0.26041667
A40: 2 | B40: {=_xlfn.IFS(C40=15,"VAN",C40=4,"CARRO PEQUENO",C40=6,"SPIN")} -> CARRO PEQUENO | C40: 4 | D40: 2 | E40: =C40-D40 -> 2 | F40: =E40/C40 -> 0.5 | G40: 0.041666667 | H40: 68 | I40: 0.93055556 | J40: 0.26041667
A41: TOTAL | C41: =SUM(C39:C40) -> 19 | D41: =SUM(D39:D40) -> 11 | E41: =SUM(E39:E40) -> 8 | F41: =E41/C41 -> 0.42105263 | G41: =AVERAGE(G39:G40) -> 0.036458333 | H41: =SUM(H39:H40) -> 176

Sheet ATIVOS
A1: Ativo? | B1: EMPRESA/SETOR | C1: GPID | D1: ROTA | E1: TURNO | F1: CARRO | G1: NOME ABREVIADO | H1: NOME COMPLETO | I1: EMPRESA | J1: CC | K1: DATA ADMISSAO | L1: ENDEREÇO COMPLETO | M1: RUA | N1: Nº | O1: BAIRRO | P1: CIDADE | Q1: PONTO DE EMBARQUE | R1: REFERÊNCIA | S1: TELEFONE | T1: DATA ALTERACAO ENDERECO
A2: SIM | C2: =_xlfn.XLOOKUP(H2,RH!$D$2:$D$116,RH!$C$2:$C$116,"Terceiro") -> 40192586 | D2: =E2&" - "&F2 -> 1T - ROTA/5 | E2: 1T | F2: ROTA/5 | G2: ACACIO. C | H2: ACACIO LUIZ LIMA CORREIA | I2: PEPSICO | J2: =_xlfn.XLOOKUP(H2,RH!$D$2:$D$116,RH!$K$2:$K$116,"Terceiro") -> BR1A294 | K2: 41102 | L2: =M2 & ", " & N2 & ", " & O2 & ", " & P2 & ", BAHIA" & ", BRASIL" -> R. FELIX PACHECO, 259, PANORAMA, FEIRA DE SANTANA, BAHIA, BRASIL | M2: R. FELIX PACHECO | N2: 259 | O2: PANORAMA | P2: FEIRA DE SANTANA | Q2: R. FELIX PACHECO N° 259 - RUA EM FRENTE AO PORTAL DESCARGA DE G BARBOSA | R2: RUA EM FRENTE AO PORTAL DESCARGA DE G BARBOSA
A3: SIM | C3: =_xlfn.XLOOKUP(H3,RH!$D$2:$D$116,RH!$C$2:$C$116,"Terceiro") -> 40285860 | D3: =E3&" - "&F3 -> 1T - ROTA/6 | E3: 1T | F3: ROTA/6 | G3: ADEMILDES | H3: ADEMILDES DA CONCEICAO | I3: PEPSICO | J3: =_xlfn.XLOOKUP(H3,RH!$D$2:$D$116,RH!$K$2:$K$116,"Terceiro") -> BR1A009 | K3: 41925 | L3: =M3 & ", " & N3 & ", " & O3 & ", " & P3 & ", BAHIA" & ", BRASIL" -> RUA RIO VERDE, 55, CONCEIÇÃO II, FEIRA DE SANTANA, BAHIA, BRASIL | M3: RUA RIO VERDE | N3: 55 | O3: CONCEIÇÃO II | P3: FEIRA DE SANTANA | Q3: RUA RIO VERDE 55 - EM FRENTE AO SALÃO NINA CABELELEIRO | R3: EM FRENTE AO SALÃO NINA CABELELEIRO
A4: SIM | C4: =_xlfn.XLOOKUP(H4,RH!$D$2:$D$116,RH!$C$2:$C$116,"Terceiro") -> 80997371 | D4: =E4&" - "&F4 -> 2T - ROTA/1 | E4: 2T | F4: ROTA/1 | G4: ADRIANO. F | H4: ADRIANO MACHADO FERREIRA | I4: PEPSICO | J4: =_xlfn.XLOOKUP(H4,RH!$D$2:$D$116,RH!$K$2:$K$116,"Terceiro") -> BR1A312 | K4: 44872 | L4: =M4 & ", " & N4 & ", " & O4 & ", " & P4 & ", BAHIA" & ", BRASIL" -> RUA AMADO BAHIA, N/A, PANORAMA, FEIRA DE SANTANA, BAHIA, BRASIL | M4: RUA AMADO BAHIA | N4: N/A | O4: PANORAMA | P4: FEIRA DE SANTANA | Q4: RUA AMADO BAHIA EM FRENTE A IGREJA DAS TESTEMUNHAS DE JEOVÁ | R4: IGREJA DAS TESTEMUNHAS DE JEOVÁ
A5: SIM | C5: =_xlfn.XLOOKUP(H5,RH!$D$2:$D$116,RH!$C$2:$C$116,"Terceiro") -> 40205767 | D5: =E5&" - "&F5 -> 3T - ROTA/1 | E5: 3T | F5: ROTA/1 | G5: Adriano. M | H5: ADRIANO DOS SANTOS MORAIS | I5: PEPSICO | J5: =_xlfn.XLOOKUP(H5,RH!$D$2:$D$116,RH!$K$2:$K$116,"Terceiro") -> BR1A312 | K5: 44872 | L5: =M5 & ", " & N5 & ", " & O5 & ", " & P5 & ", BAHIA" & ", BRASIL" -> ESCOLA TEREZA CUNHA , N/A, CALUMBI, FEIRA DE SANTANA, BAHIA, BRASIL | M5: ESCOLA TEREZA CUNHA | N5: N/A | O5: CALUMBI | P5: FEIRA DE SANTANA | Q5: Ao lado da Escola Tereza Cunha | R5: Ao lado da Escola Tereza Cunha
A6: SIM | C6: =_xlfn.XLOOKUP(H6,RH!$D$2:$D$116,RH!$C$2:$C$116,"Terceiro") -> 80315521 | D6: =E6&" - "&F6 -> ADM - ROTA/8 | E6: ADM | F6: ROTA/8 | G6: ALCIDES J | H6: ALCIDES BARBOSA DE SOUSA JUNIOR | I6: PEPSICO | J6: =_xlfn.XLOOKUP(H6,RH!$D$2:$D$116,RH!$K$2:$K$116,"Terceiro") -> BR1A294 | K6: 44242 | L6: =M6 & ", " & N6 & ", " & O6 & ", " & P6 & ", BAHIA" & ", BRASIL" -> RUA B, 41, AVIARIO, FEIRA DE SANTANA, BAHIA, BRASIL | M6: RUA B | N6: 41 | O6: AVIARIO | P6: FEIRA DE SANTANA | Q6: RUA B N°41 PONTO DE APANHA EM FRENTE A IGREJA CATOLICA | R6: IGREJA CATOLICA
A7: SIM | C7: =_xlfn.XLOOKUP(H7,RH!$D$2:$D$116,RH!$C$2:$C$116,"Terceiro") -> 80069277 | D7: =E7&" - "&F7 -> 1T - ROTA/3 | E7: 1T | F7: ROTA/3 | G7: ALEXANDRE. J | H7: ALEXANDRE SOUZA DE JESUS | I7: PEPSICO | J7: =_xlfn.XLOOKUP(H7,RH!$D$2:$D$116,RH!$K$2:$K$116,"Terceiro") -> BR1A294 | K7: 42933 | L7: =M7 & ", " & N7 & ", " & O7 & ", " & P7 & ", BAHIA" & ", BRASIL" -> RUA TUIUCA, N/A, JOÃO PAULO, FEIRA DE SANTANA, BAHIA, BRASIL | M7: RUA TUIUCA | N7: N/A | O7: JOÃO PAULO | P7: FEIRA DE SANTANA | Q7: RUA TIJUCA - EM FRENTE A PIZZARIA LAPETITOSA | R7: EM FRENTE A PIZZARIA LAPETITOSA
A8: SIM | C8: =_xlfn.XLOOKUP(H8,RH!$D$2:$D$116,RH!$C$2:$C$116,"Terceiro") -> Terceiro | D8: =E8&" - "&F8 -> 1T - ROTA/4 | E8: 1T | F8: ROTA/4 | G8: ANA PAULA DA S. | H8: ANA PAULA DA SILVA BRITO | I8: LIMGER | J8: BR4A006 | K8: 45665 | L8: =M8 & ", " & N8 & ", " & O8 & ", " & P8 & ", BAHIA" & ", BRASIL" -> RUA MANTIQUEIRA, 455, RUA NOVA, FEIRA DE SANTANA, BAHIA, BRASIL | M8: RUA MANTIQUEIRA | N8: 455 | O8: RUA NOVA | P8: FEIRA DE SANTANA | Q8: RUA MANTIQUEIRA, 455, PROX. AO CRAS | R8: PROX. AO CRAS
A9: SIM | C9: =_xlfn.XLOOKUP(H9,RH!$D$2:$D$116,RH!$C$2:$C$116,"Terceiro") -> 80038367 | D9: =E9&" - "&F9 -> ADM - ROTA/1 | E9: ADM | F9: ROTA/1 | G9: ANAILDE. C | H9: ANAILDE CRUZ ATAIDE CARVALHO | I9: PEPSICO | J9: =_xlfn.XLOOKUP(H9,RH!$D$2:$D$116,RH!$K$2:$K$116,"Terceiro") -> BR5A003 | K9: 42737 | L9: =M9 & ", " & N9 & ", " & O9 & ", " & P9 & ", BAHIA" & ", BRASIL" -> Avenida Artêmia Pires, 8147, Sim, FEIRA DE SANTANA, BAHIA, BRASIL | M9: Avenida Artêmia Pires | N9: 8147 | O9: Sim | P9: FEIRA DE SANTANA | Q9: COND. PARQUE FLORA | R9: COND. PARQUE FLORA
A10: SIM | C10: =_xlfn.XLOOKUP(H10,RH!$D$2:$D$116,RH!$C$2:$C$116,"Terceiro") -> 40172746 | D10: =E10&" - "&F10 -> ADM - ROTA/4 | E10: ADM | F10: ROTA/4 | G10: ANDERSON A. | H10: ANDERSON DE JESUS AMARAL | I10: PEPSICO | J10: =_xlfn.XLOOKUP(H10,RH!$D$2:$D$116,RH!$K$2:$K$116,"Terceiro") -> BR1A004 | K10: 40665 | L10: =M10 & ", " & N10 & ", " & O10 & ", " & P10 & ", BAHIA" & ", BRASIL" -> RUA SENADOR QUINTINO, N/A, SERRARIA BRASIL, FEIRA DE SANTANA, BAHIA, BRASIL | M10: RUA SENADOR QUINTINO | N10: N/A | O10: SERRARIA BRASIL | P10: FEIRA DE SANTANA | Q10: RUA SENADOR QUINTINO | R10: PRAÇA DA PAQUERA
A11: SIM | C11: =_xlfn.XLOOKUP(H11,RH!$D$2:$D$116,RH!$C$2:$C$116,"Terceiro") -> 81009737 | D11: =E11&" - "&F11 -> 2T - ROTA/2 | E11: 2T | F11: ROTA/2 | G11: ANDERSON. V | H11: ANDERSON FELIPE VENTURA DA SILVA | I11: PEPSICO | J11: =_xlfn.XLOOKUP(H11,RH!$D$2:$D$116,RH!$K$2:$K$116,"Terceiro") -> BR1A002 | K11: 44928 | L11: =M11 & ", " & N11 & ", " & O11 & ", " & P11 & ", BAHIA" & ", BRASIL" -> RUA VITORINO FREIRE, 822, MANGABEIRA, FEIRA DE SANTANA, BAHIA, BRASIL | M11: RUA VITORINO FREIRE | N11: 822 | O11: MANGABEIRA | P11: FEIRA DE SANTANA | Q11: RUA VITORINO FREIRE, Nº 822 EM FRENTE AO COND: BERGAMO | R11: COND: BERGAMO
A12: SIM | C12: =_xlfn.XLOOKUP(H12,RH!$D$2:$D$116,RH!$C$2:$C$116,"Terceiro") -> 80069273 | D12: =E12&" - "&F12 -> 2T - ROTA/3 | E12: 2T | F12: ROTA/3 | G12: ATAIDE. M | H12: ATAIDE DE MATOS SANTANA | I12: PEPSICO | J12: =_xlfn.XLOOKUP(H12,RH!$D$2:$D$116,RH!$K$2:$K$116,"Terceiro") -> BR1A312 | K12: 42933 | L12: =M12 & ", " & N12 & ", " & O12 & ", " & P12 & ", BAHIA" & ", BRASIL" -> AV. SANTO ANDRE, N/A, CASEB, FEIRA DE SANTANA, BAHIA, BRASIL | M12: AV. SANTO ANDRE | N12: N/A | O12: CASEB | P12: FEIRA DE SANTANA | Q12: AV. SANTO ANDRE EM FRENTE AO COND: DOM RESIDENCIAL | R12: COND: DOM RESIDENCIAL
A13: SIM | C13: =_xlfn.XLOOKUP(H13,RH!$D$2:$D$116,RH!$C$2:$C$116,"Terceiro") -> Terceiro | D13: =E13&" - "&F13 -> 1T - ROTA/8 | E13: 1T | F13: ROTA/8 | G13: CARLOS ALBERTO G. | H13: CARLOS ALBERTO GONÇALVES QUEIROZ | I13: LIMGER | J13: BR4A006 | K13: 45665 | L13: =M13 & ", " & N13 & ", " & O13 & ", " & P13 & ", BAHIA" & ", BRASIL" -> RUA DIVAL MACHADO, 18, GABRIELA, FEIRA DE SANTANA, BAHIA, BRASIL | M13: RUA DIVAL MACHADO | N13: 18 | O13: GABRIELA | P13: FEIRA DE SANTANA | Q13: RUA DIVAL MACHADO, N° 18 | R13: RUA DIVAL MACHADO, N° 18
A14: SIM | C14: =_xlfn.XLOOKUP(H14,RH!$D$2:$D$116,RH!$C$2:$C$116,"Terceiro") -> Terceiro | D14: =E14&" - "&F14 -> ADM - ROTA/5 | E14: ADM | F14: ROTA/5 | G14: CARLOS ANTONIO G. | H14: CARLOS ANTONIO GONÇALVES QUEIROZ | I14: LIMGER | J14: BR4A006 | K14: 45665 | L14: =M14 & ", " & N14 & ", " & O14 & ", " & P14 & ", BAHIA" & ", BRASIL" -> RUA DIVAL MACHADO, 18, GABRIELA, FEIRA DE SANTANA, BAHIA, BRASIL | M14: RUA DIVAL MACHADO | N14: 18 | O14: GABRIELA | P14: FEIRA DE SANTANA | Q14: RUA DIVAL MACHADO
A15: SIM | C15: =_xlfn.XLOOKUP(H15,RH!$D$2:$D$116,RH!$C$2:$C$116,"Terceiro") -> Terceiro | D15: =E15&" - "&F15 -> 2T - ROTA/1 | E15: 2T | F15: ROTA/1 | G15: CLAUDIA MARIA Q. | H15: CLAUDIA MARIA QUEIROZ | I15: LIMGER | J15: BR4A006 | K15: 45665 | L15: =M15 & ", " & N15 & ", " & O15 & ", " & P15 & ", BAHIA" & ", BRASIL" -> RUA EL SALVADOR, 38, FEIRA VII, FEIRA DE SANTANA, BAHIA, BRASIL | M15: RUA EL SALVADOR | N15: 38 | O15: FEIRA VII | P15: FEIRA DE SANTANA | Q15: RUA EL SALVADOR, Nº 38 - CENTRO AUTOMOTIVO ANDERSON CAR | R15: CENTRO AUTOMOTIVO ANDERSON CAR
A16: SIM | C16: =_xlfn.XLOOKUP(H16,RH!$D$2:$D$116,RH!$C$2:$C$116,"Terceiro") -> Terceiro | D16: =E16&" - "&F16 -> ADM - ROTA/2 | E16: ADM | F16: ROTA/2 | G16: CLAUDIO H. | H16: CLAUDIO HENRIQUE LIVEIRA SANTOS | I16: CWBEM | J16: BR5A008 | K16: 44936 | L16: =M16 & ", " & N16 & ", " & O16 & ", " & P16 & ", BAHIA" & ", BRASIL" -> Avenida Gracindo de Freitas Medeiros , N/A, MANGABEIRA, FEIRA DE SANTANA, BAHIA, BRASIL | M16: Avenida Gracindo de Freitas Medeiros | N16: N/A | O16: MANGABEIRA | P16: FEIRA DE SANTANA | Q16: COND. RESIDENCIAL FONTANA | R16: COND. RESIDENCIAL FONTANA
A17: SIM | C17: =_xlfn.XLOOKUP(H17,RH!$D$2:$D$116,RH!$C$2:$C$116,"Terceiro") -> 81226437 | D17: =E17&" - "&F17 -> ADM - ROTA/3 | E17: ADM | F17: ROTA/3 | G17: CLAUDIO R. Q. A. | H17: CLAUDIO HENRIQUE QUEIROZ ALVES | I17: PEPSICO | J17: =_xlfn.XLOOKUP(H17,RH!$D$2:$D$116,RH!$K$2:$K$116,"Terceiro") -> BR1A004 | K17: 45845 | L17: =M17 & ", " & N17 & ", " & O17 & ", " & P17 & ", BAHIA" & ", BRASIL" -> RUA LEÔCIO SANTOS, 115, SANTA MÔNICA, FEIRA DE SANTANA, BAHIA, BRASIL | M17: RUA LEÔCIO SANTOS | N17: 115 | O17: SANTA MÔNICA | P17: FEIRA DE SANTANA | Q17: RUA ATRÁS DA SEABRA HOTEL | R17: ATRÁS DA SEABRA HOTELL
A18: SIM | C18: =_xlfn.XLOOKUP(H18,RH!$D$2:$D$116,RH!$C$2:$C$116,"Terceiro") -> 80888568 | D18: =E18&" - "&F18 -> 2T - ROTA/1 | E18: 2T | F18: ROTA/1 | G18: CLAUDIONOR. C | H18: CLAUDIONOR CERQUEIRA DA COSTA | I18: PEPSICO | J18: =_xlfn.XLOOKUP(H18,RH!$D$2:$D$116,RH!$K$2:$K$116,"Terceiro") -> BR1A007 | K18: 44516 | L18: =M18 & ", " & N18 & ", " & O18 & ", " & P18 & ", BAHIA" & ", BRASIL" -> RUA DO TELEGRAFO, N/A, FRATERNIDADE, FEIRA DE SANTANA, BAHIA, BRASIL | M18: RUA DO TELEGRAFO | N18: N/A | O18: FRATERNIDADE | P18: FEIRA DE SANTANA | Q18: RUA DO TELEGRAFO, PONTO DE APANHA EM FRENTE A IGREJA QUADRANGULAR | R18: IGREJA QUADRANGULAR
A19: SIM | C19: =_xlfn.XLOOKUP(H19,RH!$D$2:$D$116,RH!$C$2:$C$116,"Terceiro") -> 80997603 | D19: =E19&" - "&F19 -> 1T - ROTA/10 | E19: 1T | F19: ROTA/10 | G19: CLEIDIANE. L | H19: CLEIDIANE DE OLIVEIRA LIMA | I19: PEPSICO | J19: =_xlfn.XLOOKUP(H19,RH!$D$2:$D$116,RH!$K$2:$K$116,"Terceiro") -> BR1A010 | K19: 44872 | L19: =M19 & ", " & N19 & ", " & O19 & ", " & P19 & ", BAHIA" & ", BRASIL" -> RUA CORRENTES, 68, CAMPO LIMPO, FEIRA DE SANTANA, BAHIA, BRASIL | M19: RUA CORRENTES | N19: 68 | O19: CAMPO LIMPO | P19: FEIRA DE SANTANA | Q19: RUA CORRENTES, Nº 68, EM FRENTE A MERCEARIA VIDEIRA | R19: EM FRENTE A MERCEARIA VIDEIRA
A20: SIM | C20: =_xlfn.XLOOKUP(H20,RH!$D$2:$D$116,RH!$C$2:$C$116,"Terceiro") -> Terceiro | D20: =E20&" - "&F20 -> 1T - ROTA/6 | E20: 1T | F20: ROTA/6 | G20: CRIS KELLY | H20: CRIS KELLY PEREIRA DA COSTA | I20: CWBEM | J20: BR5A008 | K20: 45869 | L20: =M20 & ", " & N20 & ", " & O20 & ", " & P20 & ", BAHIA" & ", BRASIL" -> RUA MARAÚ, 230, SANTO ANTÔNIO DOS PRAZERES, FEIRA DE SANTANA, BAHIA, BRASIL | M20: RUA MARAÚ | N20: 230 | O20: SANTO ANTÔNIO DOS PRAZERES | P20: FEIRA DE SANTANA | Q20: RUA MARAÚ, Nº 230 - PROX. AO PASTEL DO GALEGO | R20: PROX. AO PASTEL DO GALEGO
A21: SIM | C21: =_xlfn.XLOOKUP(H21,RH!$D$2:$D$116,RH!$C$2:$C$116,"Terceiro") -> 40216111 | D21: =E21&" - "&F21 -> 1T - ROTA/3 | E21: 1T | F21: ROTA/3 | G21: CRISTIANE. A | H21: CRISTIANE SANTOS DE OLIVEIRA ARAUJO | I21: PEPSICO | J21: =_xlfn.XLOOKUP(H21,RH!$D$2:$D$116,RH!$K$2:$K$116,"Terceiro") -> BR1A312 | K21: 41435 | L21: =M21 & ", " & N21 & ", " & O21 & ", " & P21 & ", BAHIA" & ", BRASIL" -> RUA PERIPERI, N/A, QUEIMADINHA, FEIRA DE SANTANA, BAHIA, BRASIL | M21: RUA PERIPERI | N21: N/A | O21: QUEIMADINHA | P21: FEIRA DE SANTANA | Q21: RUA PERIPERI - PROX A ESCOLA DASIS | R21: PROX A ESCOLA DASIS
A22: SIM | C22: =_xlfn.XLOOKUP(H22,RH!$D$2:$D$116,RH!$C$2:$C$116,"Terceiro") -> 81069369 | D22: =E22&" - "&F22 -> 3T - ROTA/1 | E22: 3T | F22: ROTA/1 | G22: Dacio M | H22: DACIO DA CONCEICAO MACHADO | I22: PEPSICO | J22: =_xlfn.XLOOKUP(H22,RH!$D$2:$D$116,RH!$K$2:$K$116,"Terceiro") -> BR1A294 | K22: 45152 | L22: =M22 & ", " & N22 & ", " & O22 & ", " & P22 & ", BAHIA" & ", BRASIL" -> Rua Para, 320, QUEIMADINHA, FEIRA DE SANTANA, BAHIA, BRASIL | M22: Rua Para | N22: 320 | O22: QUEIMADINHA | P22: FEIRA DE SANTANA | Q22: Rua Para, N° 320
A23: SIM | C23: =_xlfn.XLOOKUP(H23,RH!$D$2:$D$116,RH!$C$2:$C$116,"Terceiro") -> 80916371 | D23: =E23&" - "&F23 -> 2T - ROTA/4 | E23: 2T | F23: ROTA/4 | G23: DAIANE. R | H23: DAIANE DE OLIVEIRA RODRIGUES | I23: PEPSICO | J23: =_xlfn.XLOOKUP(H23,RH!$D$2:$D$116,RH!$K$2:$K$116,"Terceiro") -> BR1A312 | K23: 44622 | L23: =M23 & ", " & N23 & ", " & O23 & ", " & P23 & ", BAHIA" & ", BRASIL" -> RUA BREVES, 33, LIMOEIRO, LIMOEIRO, BAHIA, BRASIL | M23: RUA BREVES | N23: 33 | O23: LIMOEIRO | P23: LIMOEIRO | Q23: RUA BREVES, Nº 33, PONTO DE APANHA EM FRENTE A FÁBRICA DE VELAS | R23: FÁBRICA DE VELAS
A24: SIM | C24: =_xlfn.XLOOKUP(H24,RH!$D$2:$D$116,RH!$C$2:$C$116,"Terceiro") -> 80159517 | D24: =E24&" - "&F24 -> ADM - ROTA/1 | E24: ADM | F24: ROTA/1 | G24: DAIANE X. | H24: DAIANE SILVA XAVIER | I24: PEPSICO | J24: =_xlfn.XLOOKUP(H24,RH!$D$2:$D$116,RH!$K$2:$K$116,"Terceiro") -> BR1A002 | K24: 43451 | L24: =M24 & ", " & N24 & ", " & O24 & ", " & P24 & ", BAHIA" & ", BRASIL" -> RUA CAMBORIÚ, 50, Sim, FEIRA DE SANTANA, BAHIA, BRASIL | M24: RUA CAMBORIÚ | N24: 50 | O24: Sim | P24: FEIRA DE SANTANA | Q24: LOCAL DE APANHA EM FRENTE A CAOA CHERY | R24: EM FRENTE A CAOA CHERY
A25: SIM | C25: =_xlfn.XLOOKUP(H25,RH!$D$2:$D$116,RH!$C$2:$C$116,"Terceiro") -> 81145746 | D25: =E25&" - "&F25 -> 2T - ROTA/3 | E25: 2T | F25: ROTA/3 | G25: DERALDO S. | H25: DERALDO DOS SANTOS JUNIOR | I25: PEPSICO | J25: =_xlfn.XLOOKUP(H25,RH!$D$2:$D$116,RH!$K$2:$K$116,"Terceiro") -> BR1A312 | K25: 45425 | L25: =M25 & ", " & N25 & ", " & O25 & ", " & P25 & ", BAHIA" & ", BRASIL" -> RUA CARLOS LADARES, 1058, QUEIMADINHA, FEIRA DE SANTANA, BAHIA, BRASIL | M25: RUA CARLOS LADARES | N25: 1058 | O25: QUEIMADINHA | P25: FEIRA DE SANTANA | Q25: RUA CARLOS LADARES, N°. 1058 - EM FRENTE A CLINICA UNACON | R25: CLINICA UNACON
A26: SIM | C26: =_xlfn.XLOOKUP(H26,RH!$D$2:$D$116,RH!$C$2:$C$116,"Terceiro") -> 80258585 | D26: =E26&" - "&F26 -> 3T - ROTA/1 | E26: 3T | F26: ROTA/1 | G26: Ecio. R | H26: ECIO CONCEICAO DOS REIS | I26: PEPSICO | J26: =_xlfn.XLOOKUP(H26,RH!$D$2:$D$116,RH!$K$2:$K$116,"Terceiro") -> BR1A004 | K26: 43997 | L26: =M26 & ", " & N26 & ", " & O26 & ", " & P26 & ", BAHIA" & ", BRASIL" -> Rua Santos, 101, CASEB, FEIRA DE SANTANA, BAHIA, BRASIL | M26: Rua Santos | N26: 101 | O26: CASEB | P26: FEIRA DE SANTANA | Q26: Rua Santos, N° 101
A27: SIM | C27: =_xlfn.XLOOKUP(H27,RH!$D$2:$D$116,RH!$C$2:$C$116,"Terceiro") -> Terceiro | D27: =E27&" - "&F27 -> 2T - ROTA/1 | E27: 2T | F27: ROTA/1 | G27: EDIPO P. S. | H27: ÉDIPO PINHEIRO SILVA | I27: CWBEM | J27: BR5A008 | K27: 45811 | L27: =M27 & ", " & N27 & ", " & O27 & ", " & P27 & ", BAHIA" & ", BRASIL" -> RUA DOUTOR MACÁRIO CERQUEIRA, 1147, MUCHILA, FEIRA DE SANTANA, BAHIA, BRASIL | M27: RUA DOUTOR MACÁRIO CERQUEIRA | N27: 1147 | O27: MUCHILA | P27: FEIRA DE SANTANA | Q27: RUA DOUTOR MACÁRIO CERQUEIRA, 1147, CONDOMINIO PRINCESA DO SERTÃO | R27: CONDOMINIO PRINCESA DO SERTÃO
A28: SIM | C28: =_xlfn.XLOOKUP(H28,RH!$D$2:$D$116,RH!$C$2:$C$116,"Terceiro") -> 80888181 | D28: =E28&" - "&F28 -> 2T - ROTA/4 | E28: 2T | F28: ROTA/4 | G28: EDMILSON. L | H28: EDMILSON LOPES DE OLIVEIRA | I28: PEPSICO | J28: =_xlfn.XLOOKUP(H28,RH!$D$2:$D$116,RH!$K$2:$K$116,"Terceiro") -> BR1A294 | K28: 44516 | L28: =M28 & ", " & N28 & ", " & O28 & ", " & P28 & ", BAHIA" & ", BRASIL" -> PRAÇA DO LIMOEIRO, N/A, LIMOEIRO, LIMOEIRO, BAHIA, BRASIL | M28: PRAÇA DO LIMOEIRO | N28: N/A | O28: LIMOEIRO | P28: LIMOEIRO | Q28: PRAÇA DO LIMOEIRO, EM FRENTE AO MERCADO MUNICIPAL | R28: MERCADO MUNICIPAL
A29: SIM | C29: =_xlfn.XLOOKUP(H29,RH!$D$2:$D$116,RH!$C$2:$C$116,"Terceiro") -> Terceiro | D29: =E29&" - "&F29 -> 1T - ROTA/8 | E29: 1T | F29: ROTA/8 | G29: EDINEIDE DA S. | H29: EDNEIDE DA SILVA TITO | I29: LIMGER | J29: BR4A006 | K29: 45665 | L29: =M29 & ", " & N29 & ", " & O29 & ", " & P29 & ", BAHIA" & ", BRASIL" -> RUA AEROLINHA ESPANHA, 80, GEORGE AMERICO, FEIRA DE SANTANA, BAHIA, BRASIL | M29: RUA AEROLINHA ESPANHA | N29: 80 | O29: GEORGE AMERICO | P29: FEIRA DE SANTANA | Q29: RUA AEROLINHA ESPANHA, N° 80, PROX: POLICLINICA DE GEORGE AMERICO | R29: PROX: POLICLINICA DE GEORGE AMERICO
A30: SIM | C30: =_xlfn.XLOOKUP(H30,RH!$D$2:$D$116,RH!$C$2:$C$116,"Terceiro") -> 81218214 | D30: =E30&" - "&F30 -> 1T - ROTA/5 | E30: 1T | F30: ROTA/5 | G30: EDUARDO S. | H30: EDUARDO DE ALMEIDA SILVA | I30: PEPSICO | J30: =_xlfn.XLOOKUP(H30,RH!$D$2:$D$116,RH!$K$2:$K$116,"Terceiro") -> BR1A004 | K30: 45789 | L30: =M30 & ", " & N30 & ", " & O30 & ", " & P30 & ", BAHIA" & ", BRASIL" -> RUA SEIS, 7, FEIRA VII, FEIRA DE SANTANA, BAHIA, BRASIL | M30: RUA SEIS | N30: 7 | O30: FEIRA VII | P30: FEIRA DE SANTANA | Q30: RUA SEIS, N° 7 - COM.J ELZA AZEVEDO | R30: COM.J ELZA AZEVEDO
A31: SIM | C31: =_xlfn.XLOOKUP(H31,RH!$D$2:$D$116,RH!$C$2:$C$116,"Terceiro") -> 40185173 | D31: =E31&" - "&F31 -> 3T - ROTA/1 | E31: 3T | F31: ROTA/1 | G31: Edvan. B | H31: EDVAN SOUZA SANTA BARBARA | I31: PEPSICO | J31: =_xlfn.XLOOKUP(H31,RH!$D$2:$D$116,RH!$K$2:$K$116,"Terceiro") -> BR1A007 | K31: 40924 | L31: =M31 & ", " & N31 & ", " & O31 & ", " & P31 & ", BAHIA" & ", BRASIL" -> Rua Camboriú, 50, SIM, FEIRA DE SANTANA, BAHIA, BRASIL | M31: Rua Camboriú | N31: 50 | O31: SIM | P31: FEIRA DE SANTANA | Q31: Rua Camboriú,N° 50, Ponto de apanha em frente a concessionaria Chery | R31: Atras do Shopping Avenida
A32: SIM | C32: =_xlfn.XLOOKUP(H32,RH!$D$2:$D$116,RH!$C$2:$C$116,"Terceiro") -> 40175823 | D32: =E32&" - "&F32 -> 2T - ROTA/5 | E32: 2T | F32: ROTA/5 | G32: ELAINE. G | H32: ELAINE BATISTA GONCALVES LIMA | I32: PEPSICO | J32: =_xlfn.XLOOKUP(H32,RH!$D$2:$D$116,RH!$K$2:$K$116,"Terceiro") -> BR1A294 | K32: 40756 | L32: =M32 & ", " & N32 & ", " & O32 & ", " & P32 & ", BAHIA" & ", BRASIL" -> RUA PROFª. ELISA FERNANDES, 23, CAMPO LIMPO, FEIRA DE SANTANA, BAHIA, BRASIL | M32: RUA PROFª. ELISA FERNANDES | N32: 23 | O32: CAMPO LIMPO | P32: FEIRA DE SANTANA | Q32: RUA PROFª. ELISA FERNANDES,Nº 23, PONTO DE APANHA BARBEARIA JB | R32: BARBEARIA JB
A33: SIM | C33: =_xlfn.XLOOKUP(H33,RH!$D$2:$D$116,RH!$C$2:$C$116,"Terceiro") -> 80851941 | D33: =E33&" - "&F33 -> 1T - ROTA/5 | E33: 1T | F33: ROTA/5 | G33: ELIANA. A | H33: ELIANA DE ALMEIDA OLIVEIRA | I33: PEPSICO | J33: =_xlfn.XLOOKUP(H33,RH!$D$2:$D$116,RH!$K$2:$K$116,"Terceiro") -> BR1A010 | K33: 44382 | L33: =M33 & ", " & N33 & ", " & O33 & ", " & P33 & ", BAHIA" & ", BRASIL" -> RUA PROJETADA, 27, PANORAMA, FEIRA DE SANTANA, BAHIA, BRASIL | M33: RUA PROJETADA | N33: 27 | O33: PANORAMA | P33: FEIRA DE SANTANA | Q33: RUA PROJETADA, N° 27 - RUA LATERAL DO USF PANORAMA 3 | R33: RUA LATERAL DO USF PANORAMA 3
A34: SIM | C34: =_xlfn.XLOOKUP(H34,RH!$D$2:$D$116,RH!$C$2:$C$116,"Terceiro") -> 40285831 | D34: =E34&" - "&F34 -> 1T - ROTA/2 | E34: 1T | F34: ROTA/2 | G34: ELIAS. F | H34: ELIAS MOREIRA DA FONSECA | I34: PEPSICO | J34: =_xlfn.XLOOKUP(H34,RH!$D$2:$D$116,RH!$K$2:$K$116,"Terceiro") -> BR1A010 | K34: 41925 | L34: =M34 & ", " & N34 & ", " & O34 & ", " & P34 & ", BAHIA" & ", BRASIL" -> PRAÇA SÃO ROQUE, N/A, MATINHA, MATINHA, BAHIA, BRASIL | M34: PRAÇA SÃO ROQUE | N34: N/A | O34: MATINHA | P34: MATINHA | Q34: PRAÇA SÃO ROQUE | R34: PRAÇA SÃO ROQUE
A35: SIM | C35: =_xlfn.XLOOKUP(H35,RH!$D$2:$D$116,RH!$C$2:$C$116,"Terceiro") -> 80997938 | D35: =E35&" - "&F35 -> 1T - ROTA/5 | E35: 1T | F35: ROTA/5 | G35: ELICELIA. C | H35: ELICELIA CAMPOS SANTOS | I35: PEPSICO | J35: =_xlfn.XLOOKUP(H35,RH!$D$2:$D$116,RH!$K$2:$K$116,"Terceiro") -> BR1A009 | K35: 44872 | L35: =M35 & ", " & N35 & ", " & O35 & ", " & P35 & ", BAHIA" & ", BRASIL" -> RESIDENCIAL MORADA FELIZ, RUA 1, N/A, FRATERNIDADE, FEIRA DE SANTANA, BAHIA, BRASIL | M35: RESIDENCIAL MORADA FELIZ, RUA 1 | N35: N/A | O35: FRATERNIDADE | P35: FEIRA DE SANTANA | Q35: RESIDENCIAL MORADA FELIZ, RUA 1, PONTO DE APANHA EM FRENTE A FABRICA VIVA NATUREZA | R35: EM FRENTE A FABRICA VIVA NATUREZA
A36: SIM | C36: =_xlfn.XLOOKUP(H36,RH!$D$2:$D$116,RH!$C$2:$C$116,"Terceiro") -> Terceiro | D36: =E36&" - "&F36 -> ADM ESPECIAL - ROTA/5 | E36: ADM ESPECIAL | F36: ROTA/5 | G36: ELINE P. | H36: ELINE PEREIRA ALVES | I36: LIMGER | J36: BR4A006 | K36: 45665 | L36: =M36 & ", " & N36 & ", " & O36 & ", " & P36 & ", BAHIA" & ", BRASIL" -> RUA AEROLINA ESPANHA, N/A, GEORGE AMERICO, FEIRA DE SANTANA, BAHIA, BRASIL | M36: RUA AEROLINA ESPANHA | N36: N/A | O36: GEORGE AMERICO | P36: FEIRA DE SANTANA | Q36: IGREJA ARCA DA ALIANÇA, EM FRENTE AO MERCADINHO DE DETE | R36: IGREJA ARCA DA ALIANÇA, EM FRENTE AO MERCADINHO DE DETE
A37: SIM | C37: =_xlfn.XLOOKUP(H37,RH!$D$2:$D$116,RH!$C$2:$C$116,"Terceiro") -> 40277251 | D37: =E37&" - "&F37 -> 1T - ROTA/4 | E37: 1T | F37: ROTA/4 | G37: ELIOMAR. P | H37: ELIOMAR CARVALHO DA PAIXAO | I37: PEPSICO | J37: =_xlfn.XLOOKUP(H37,RH!$D$2:$D$116,RH!$K$2:$K$116,"Terceiro") -> BR1A010 | K37: 41792 | L37: =M37 & ", " & N37 & ", " & O37 & ", " & P37 & ", BAHIA" & ", BRASIL" -> AV. RUBENS DE CARVALHO, 265, VILA OLIMPIA, FEIRA DE SANTANA, BAHIA, BRASIL | M37: AV. RUBENS DE CARVALHO | N37: 265 | O37: VILA OLIMPIA | P37: FEIRA DE SANTANA | Q37: AV. RUBENS DE CARVALHO, N° 265, EM FRENTE AO COND. SÃO BENTO | R37: EM FRENTE AO COND. SÃO BENTO
A38: SIM | C38: =_xlfn.XLOOKUP(H38,RH!$D$2:$D$116,RH!$C$2:$C$116,"Terceiro") -> 40297022 | D38: =E38&" - "&F38 -> 1T - ROTA/8 | E38: 1T | F38: ROTA/8 | G38: EMANUEL A. | H38: EMANUEL ALMEIDA DE LIMA | I38: PEPSICO | J38: =_xlfn.XLOOKUP(H38,RH!$D$2:$D$116,RH!$K$2:$K$116,"Terceiro") -> BR1A312 | K38: 42142 | L38: =M38 & ", " & N38 & ", " & O38 & ", " & P38 & ", BAHIA" & ", BRASIL" -> RUA ALTO DE SANTANA, N/A, GABRIELA, FEIRA DE SANTANA, BAHIA, BRASIL | M38: RUA ALTO DE SANTANA | N38: N/A | O38: GABRIELA | P38: FEIRA DE SANTANA | Q38: RUA ALTO DE SANTANA EM FRENTE AO MERCADO 3 IRMÃO | R38: EM FRENTE AO MERCADO 3 IRMÃO
A39: SIM | C39: =_xlfn.XLOOKUP(H39,RH!$D$2:$D$116,RH!$C$2:$C$116,"Terceiro") -> 80185857 | D39: =E39&" - "&F39 -> 2T - ROTA/2 | E39: 2T | F39: ROTA/2 | G39: EMANUELLA S. | H39: EMANUELA BATISTA SANTOS | I39: PEPSICO | J39: =_xlfn.XLOOKUP(H39,RH!$D$2:$D$116,RH!$K$2:$K$116,"Terceiro") -> BR1A312 | K39: 43598 | L39: =M39 & ", " & N39 & ", " & O39 & ", " & P39 & ", BAHIA" & ", BRASIL" -> RUA QUINTANDUBA, 103, CONCEIÇÃO I, FEIRA DE SANTANA, BAHIA, BRASIL | M39: RUA QUINTANDUBA | N39: 103 | O39: CONCEIÇÃO I | P39: FEIRA DE SANTANA | Q39: RUA QUINTANDUBA 103 EM FRENTE AO MERCADINHO FAMILIA SOUZA | R39: MERCADINHO FAMILIA SOUZA
A40: SIM | C40: =_xlfn.XLOOKUP(H40,RH!$D$2:$D$116,RH!$C$2:$C$116,"Terceiro") -> 80143927 | D40: =E40&" - "&F40 -> 2T - ROTA/5 | E40: 2T | F40: ROTA/5 | G40: ESMERALDA. M | H40: ESMERALDA MARTINS DO NASCIMENTO MAGALHAES | I40: PEPSICO | J40: =_xlfn.XLOOKUP(H40,RH!$D$2:$D$116,RH!$K$2:$K$116,"Terceiro") -> BR1A312 | K40: 43353 | L40: =M40 & ", " & N40 & ", " & O40 & ", " & P40 & ", BAHIA" & ", BRASIL" -> RUA J, 26, CIDADE NOVA, FEIRA DE SANTANA, BAHIA, BRASIL | M40: RUA J | N40: 26 | O40: CIDADE NOVA | P40: FEIRA DE SANTANA | Q40: RUA J, N° 26,PONTO DE APANHA BARATA MOTO PEÇAS | R40: BARATA MOTO PEÇAS
...

Sheet RH
A1: VICE PRESIDÊNCIA | B1: DIRETORIA | C1: GPID | D1: NOME | E1: Observação | F1: CODIGOCARGO | G1: CARGO | H1: Position Code | I1: CODLOCAL | J1: DESCLOCAL | K1: CODCCUSTO | L1: DESCCCUSTO | M1: DATAADMISSAO | N1: ANIVERSÁRIO | O1: Horário | P1: GPID - GESTOR IMEDIATO | Q1: GESTOR IMEDIATO | R1: EMAIL CORPORATIVO | S1: STATUS | T1: SETOR
A2: Total Operacoes | B2: Manufatura Nutrition | C2: 40277251 | D2: ELIOMAR CARVALHO DA PAIXAO | E2: Fábrica Feira de Santana | F2: 5031 | G2: OPERADOR MULTIFUNCIONAL | H2: P50540268 | I2: 20009 | J2: FÁBRICA FEIRA DE SANTANA | K2: BR1A010 | L2: PRODUCAO MAGICO BA | M2: 41792 | N2: 13/7 | O2: 06:00 10:00 11:10 14:30 | P2: 40172715 | Q2: ALINE SOARES ANDRADE GAVAZZA | R2: eliomar.paixao@pepsico.com | S2: A | T2: {=IF(_xlfn.XLOOKUP(1, (Tabela25[CARGO] = Tabela2[[#This Row],[CARGO]]) * (Tabela25[CC] = Tabela2[[#This Row],[DESCCCUSTO]]), Tabela25[SETOR/EMPRESA], "INSERIR SETOR")="", "INSERIR SETOR", _xlfn.XLOOKUP(1, (Tabela25[CARGO] = Tabela2[[#This Row],[CARGO]]) * (Tabela25[CC] = Tabela2[[#This Row],[DESCCCUSTO]]), Tabela25[SETOR/EMPRESA], "INSERIR SETOR"))} -> 0
A3: Total Operacoes | B3: Manufatura Nutrition | C3: 40213379 | D3: VALLENO LIMA SENA | E3: Fábrica Feira de Santana | F3: 5031 | G3: OPERADOR MULTIFUNCIONAL | H3: P00190666 | I3: 20009 | J3: FÁBRICA FEIRA DE SANTANA | K3: BR1A010 | L3: PRODUCAO MAGICO BA | M3: 41372 | N3: 12/8 | O3: 06:00 10:00 11:10 14:30 | P3: 40172715 | Q3: ALINE SOARES ANDRADE GAVAZZA | R3: VALLENO.SENA@pepsico.com | S3: A | T3: {=IF(_xlfn.XLOOKUP(1, (Tabela25[CARGO] = Tabela2[[#This Row],[CARGO]]) * (Tabela25[CC] = Tabela2[[#This Row],[DESCCCUSTO]]), Tabela25[SETOR/EMPRESA], "INSERIR SETOR")="", "INSERIR SETOR", _xlfn.XLOOKUP(1, (Tabela25[CARGO] = Tabela2[[#This Row],[CARGO]]) * (Tabela25[CC] = Tabela2[[#This Row],[DESCCCUSTO]]), Tabela25[SETOR/EMPRESA], "INSERIR SETOR"))} -> 0
A4: Total Operacoes | B4: Manufatura Nutrition | C4: 40285831 | D4: ELIAS MOREIRA DA FONSECA | E4: Fábrica Feira de Santana | F4: 5031 | G4: OPERADOR MULTIFUNCIONAL | H4: P00190669 | I4: 20009 | J4: FÁBRICA FEIRA DE SANTANA | K4: BR1A010 | L4: PRODUCAO MAGICO BA | M4: 41925 | N4: 17/6 | O4: 06:00 10:00 11:10 14:30 | P4: 40172715 | Q4: ALINE SOARES ANDRADE GAVAZZA | R4: ELIAS.DAFONSECA@pepsico.com | S4: A | T4: {=IF(_xlfn.XLOOKUP(1, (Tabela25[CARGO] = Tabela2[[#This Row],[CARGO]]) * (Tabela25[CC] = Tabela2[[#This Row],[DESCCCUSTO]]), Tabela25[SETOR/EMPRESA], "INSERIR SETOR")="", "INSERIR SETOR", _xlfn.XLOOKUP(1, (Tabela25[CARGO] = Tabela2[[#This Row],[CARGO]]) * (Tabela25[CC] = Tabela2[[#This Row],[DESCCCUSTO]]), Tabela25[SETOR/EMPRESA], "INSERIR SETOR"))} -> 0
A5: Total Operacoes | B5: Manufatura Nutrition | C5: 80310115 | D5: MIRIAN RANGEL SILVA SANTANA | E5: Fábrica Feira de Santana | F5: 5179 | G5: AUXILIAR DE PRODUCAO | H5: P00073945 | I5: 20009 | J5: FÁBRICA FEIRA DE SANTANA | K5: BR1A010 | L5: PRODUCAO MAGICO BA | M5: 44214 | N5: 30/6 | O5: 06:00 10:00 11:10 14:30 | P5: 40172715 | Q5: ALINE SOARES ANDRADE GAVAZZA | R5: MIRIAN.SANTANA@pepsico.com | S5: A | T5: {=IF(_xlfn.XLOOKUP(1, (Tabela25[CARGO] = Tabela2[[#This Row],[CARGO]]) * (Tabela25[CC] = Tabela2[[#This Row],[DESCCCUSTO]]), Tabela25[SETOR/EMPRESA], "INSERIR SETOR")="", "INSERIR SETOR", _xlfn.XLOOKUP(1, (Tabela25[CARGO] = Tabela2[[#This Row],[CARGO]]) * (Tabela25[CC] = Tabela2[[#This Row],[DESCCCUSTO]]), Tabela25[SETOR/EMPRESA], "INSERIR SETOR"))} -> 0
A6: Total Operacoes | B6: Manufatura Nutrition | C6: 80851941 | D6: ELIANA DE ALMEIDA OLIVEIRA | E6: Fábrica Feira de Santana | F6: 5179 | G6: AUXILIAR DE PRODUCAO | H6: P00073627 | I6: 20009 | J6: FÁBRICA FEIRA DE SANTANA | K6: BR1A010 | L6: PRODUCAO MAGICO BA | M6: 44382 | N6: 3/4 | O6: 06:00 10:00 11:10 14:30 | P6: 40172715 | Q6: ALINE SOARES ANDRADE GAVAZZA | R6: ELIANA.OLIVEIRA@pepsico.com | S6: A | T6: {=IF(_xlfn.XLOOKUP(1, (Tabela25[CARGO] = Tabela2[[#This Row],[CARGO]]) * (Tabela25[CC] = Tabela2[[#This Row],[DESCCCUSTO]]), Tabela25[SETOR/EMPRESA], "INSERIR SETOR")="", "INSERIR SETOR", _xlfn.XLOOKUP(1, (Tabela25[CARGO] = Tabela2[[#This Row],[CARGO]]) * (Tabela25[CC] = Tabela2[[#This Row],[DESCCCUSTO]]), Tabela25[SETOR/EMPRESA], "INSERIR SETOR"))} -> 0
A7: Total Operacoes | B7: Manufatura Nutrition | C7: 80873151 | D7: LUIZ EDUARDO DE OLIVEIRA SANTOS | E7: Fábrica Feira de Santana | F7: 5031 | G7: OPERADOR MULTIFUNCIONAL | H7: P00190670 | I7: 20009 | J7: FÁBRICA FEIRA DE SANTANA | K7: BR1A010 | L7: PRODUCAO MAGICO BA | M7: 44459 | N7: 24/1 | O7: 06:00 10:00 11:10 14:30 | P7: 40172715 | Q7: ALINE SOARES ANDRADE GAVAZZA | R7: LUIZEDUARDO.SANTOS@pepsico.com | S7: A | T7: {=IF(_xlfn.XLOOKUP(1, (Tabela25[CARGO] = Tabela2[[#This Row],[CARGO]]) * (Tabela25[CC] = Tabela2[[#This Row],[DESCCCUSTO]]), Tabela25[SETOR/EMPRESA], "INSERIR SETOR")="", "INSERIR SETOR", _xlfn.XLOOKUP(1, (Tabela25[CARGO] = Tabela2[[#This Row],[CARGO]]) * (Tabela25[CC] = Tabela2[[#This Row],[DESCCCUSTO]]), Tabela25[SETOR/EMPRESA], "INSERIR SETOR"))} -> 0
A8: Total Operacoes | B8: Manufatura Nutrition | C8: 80997603 | D8: CLEIDIANE DE OLIVEIRA LIMA | E8: Fábrica Feira de Santana | F8: 5179 | G8: AUXILIAR DE PRODUCAO | H8: P00190680 | I8: 20009 | J8: FÁBRICA FEIRA DE SANTANA | K8: BR1A010 | L8: PRODUCAO MAGICO BA | M8: 44872 | N8: 27/3 | O8: 06:00 10:00 11:10 14:30 | P8: 40172715 | Q8: ALINE SOARES ANDRADE GAVAZZA | R8: CLEIDIANE.LIMA@pepsico.com | S8: A | T8: {=IF(_xlfn.XLOOKUP(1, (Tabela25[CARGO] = Tabela2[[#This Row],[CARGO]]) * (Tabela25[CC] = Tabela2[[#This Row],[DESCCCUSTO]]), Tabela25[SETOR/EMPRESA], "INSERIR SETOR")="", "INSERIR SETOR", _xlfn.XLOOKUP(1, (Tabela25[CARGO] = Tabela2[[#This Row],[CARGO]]) * (Tabela25[CC] = Tabela2[[#This Row],[DESCCCUSTO]]), Tabela25[SETOR/EMPRESA], "INSERIR SETOR"))} -> 0
A9: Total Operacoes | B9: Manufatura Nutrition | C9: 81168348 | D9: MARIANA SILVA DOS ANJOS | E9: Fábrica Feira de Santana | F9: 5179 | G9: AUXILIAR DE PRODUCAO | H9: P50838653 | I9: 20009 | J9: FÁBRICA FEIRA DE SANTANA | K9: BR1A010 | L9: PRODUCAO MAGICO BA | M9: 45509 | N9: 3/3 | O9: 06:00 10:00 11:10 14:30 | P9: 40172715 | Q9: ALINE SOARES ANDRADE GAVAZZA | R9: MARIANA.DOSANJOS@pepsico.com | S9: A | T9: {=IF(_xlfn.XLOOKUP(1, (Tabela25[CARGO] = Tabela2[[#This Row],[CARGO]]) * (Tabela25[CC] = Tabela2[[#This Row],[DESCCCUSTO]]), Tabela25[SETOR/EMPRESA], "INSERIR SETOR")="", "INSERIR SETOR", _xlfn.XLOOKUP(1, (Tabela25[CARGO] = Tabela2[[#This Row],[CARGO]]) * (Tabela25[CC] = Tabela2[[#This Row],[DESCCCUSTO]]), Tabela25[SETOR/EMPRESA], "INSERIR SETOR"))} -> 0
A10: Total Operacoes | B10: Manufatura Nutrition | C10: 81252475 | D10: TIAGO SANTOS VENAS | E10: Fábrica Feira de Santana | F10: 5179 | G10: AUXILIAR DE PRODUCAO | H10: P00073640 | I10: 20009 | J10: FÁBRICA FEIRA DE SANTANA | K10: BR1A010 | L10: PRODUCAO MAGICO BA | M10: 46034 | N10: 10/6 | O10: 14:20 18:00 19:10 22:45 | P10: 40172715 | Q10: ALINE SOARES ANDRADE GAVAZZA | R10: tiagovenas964@gmail.com | S10: A | T10: {=IF(_xlfn.XLOOKUP(1, (Tabela25[CARGO] = Tabela2[[#This Row],[CARGO]]) * (Tabela25[CC] = Tabela2[[#This Row],[DESCCCUSTO]]), Tabela25[SETOR/EMPRESA], "INSERIR SETOR")="", "INSERIR SETOR", _xlfn.XLOOKUP(1, (Tabela25[CARGO] = Tabela2[[#This Row],[CARGO]]) * (Tabela25[CC] = Tabela2[[#This Row],[DESCCCUSTO]]), Tabela25[SETOR/EMPRESA], "INSERIR SETOR"))} -> 0
A11: Total Operacoes | B11: Manufatura Nutrition | C11: 40285860 | D11: ADEMILDES DA CONCEICAO | E11: Fábrica Feira de Santana | F11: 5031 | G11: OPERADOR MULTIFUNCIONAL | H11: P00190665 | I11: 20009 | J11: FÁBRICA FEIRA DE SANTANA | K11: BR1A009 | L11: PRODUCAO TODDY BA | M11: 41925 | N11: 1/8 | O11: 06:00 10:00 11:00 14:20 | P11: 40172715 | Q11: ALINE SOARES ANDRADE GAVAZZA | R11: Ademildes.DaConceicao1@pepsico.com | S11: A | T11: {=IF(_xlfn.XLOOKUP(1, (Tabela25[CARGO] = Tabela2[[#This Row],[CARGO]]) * (Tabela25[CC] = Tabela2[[#This Row],[DESCCCUSTO]]), Tabela25[SETOR/EMPRESA], "INSERIR SETOR")="", "INSERIR SETOR", _xlfn.XLOOKUP(1, (Tabela25[CARGO] = Tabela2[[#This Row],[CARGO]]) * (Tabela25[CC] = Tabela2[[#This Row],[DESCCCUSTO]]), Tabela25[SETOR/EMPRESA], "INSERIR SETOR"))} -> 0
A12: Total Operacoes | B12: Manufatura Nutrition | C12: 80084668 | D12: SILVIO FERNANDO DE CARVALHO VASCONCELOS | E12: Fábrica Feira de Santana | F12: 5179 | G12: AUXILIAR DE PRODUCAO | H12: P00107081 | I12: 20009 | J12: FÁBRICA FEIRA DE SANTANA | K12: BR1A009 | L12: PRODUCAO TODDY BA | M12: 43024 | N12: 11/2 | O12: 06:00 10:00 11:10 14:30 | P12: 40172715 | Q12: ALINE SOARES ANDRADE GAVAZZA | R12: SILVIOFERNANDO.VASCONCELOS@pepsico.com | S12: A | T12: {=IF(_xlfn.XLOOKUP(1, (Tabela25[CARGO] = Tabela2[[#This Row],[CARGO]]) * (Tabela25[CC] = Tabela2[[#This Row],[DESCCCUSTO]]), Tabela25[SETOR/EMPRESA], "INSERIR SETOR")="", "INSERIR SETOR", _xlfn.XLOOKUP(1, (Tabela25[CARGO] = Tabela2[[#This Row],[CARGO]]) * (Tabela25[CC] = Tabela2[[#This Row],[DESCCCUSTO]]), Tabela25[SETOR/EMPRESA], "INSERIR SETOR"))} -> 0
A13: Total Operacoes | B13: Manufatura Nutrition | C13: 80851934 | D13: MARCOS WELINGTON VIANA MENEZES | E13: Fábrica Feira de Santana | F13: 5031 | G13: OPERADOR MULTIFUNCIONAL | H13: P00190668 | I13: 20009 | J13: FÁBRICA FEIRA DE SANTANA | K13: BR1A009 | L13: PRODUCAO TODDY BA | M13: 44382 | N13: 25/1 | O13: 06:00 10:00 11:10 14:30 | P13: 40172715 | Q13: ALINE SOARES ANDRADE GAVAZZA | R13: MARCOS.MENEZES@pepsico.com | S13: A | T13: {=IF(_xlfn.XLOOKUP(1, (Tabela25[CARGO] = Tabela2[[#This Row],[CARGO]]) * (Tabela25[CC] = Tabela2[[#This Row],[DESCCCUSTO]]), Tabela25[SETOR/EMPRESA], "INSERIR SETOR")="", "INSERIR SETOR", _xlfn.XLOOKUP(1, (Tabela25[CARGO] = Tabela2[[#This Row],[CARGO]]) * (Tabela25[CC] = Tabela2[[#This Row],[DESCCCUSTO]]), Tabela25[SETOR/EMPRESA], "INSERIR SETOR"))} -> 0
... A116: Total Operacoes | B116: Manufatura | C116: 80304771 | D116: KATARYNNA SANTOS DE ARAUJO | E116: Fábrica Feira de Santana | F116: 2193 | G116: ANALISTA DE MELHORIA CONTINUA SR | H116: P50569559 | I116: 20009 | J116: FÁBRICA FEIRA DE SANTANA | K116: BR1A054 | L116: ATB & LSS MANUF PROD | M116: 44179 | N116: 30/7 | O116: 07:30 12:00 13:00 17:18 | P116: 40050609 | Q116: ROSIMAYRE DA SILVA SOUSA | R116: katarynna.araujo@pepsico.com | S116: A | T116: {=IF(_xlfn.XLOOKUP(1, (Tabela25[CARGO] = Tabela2[[#This Row],[CARGO]]) * (Tabela25[CC] = Tabela2[[#This Row],[DESCCCUSTO]]), Tabela25[SETOR/EMPRESA], "INSERIR SETOR")="", "INSERIR SETOR", _xlfn.XLOOKUP(1, (Tabela25[CARGO] = Tabela2[[#This Row],[CARGO]]) * (Tabela25[CC] = Tabela2[[#This Row],[DESCCCUSTO]]), Tabela25[SETOR/EMPRESA], "INSERIR SETOR"))} -> 0

Sheet SETORES E EMPRESAS
A1: CC | B1: CARGO | C1: SETOR/EMPRESA
A2: ASSISTENTE LOGISTICA SR | B2: ALM INSUMOS BA | C2: ALMOXARIFADO / EXPEDIÇÃO
A3: ALMOXARIFE | B3: ALMOXARIFADO PECAS | C3: ALMOXARIFADO
A4: ANALISTA DE MELHORIA CONTINUA SR | B4: ATB & LSS MANUF PROD
A5: AUXILIAR DE PRODUCAO | B5: COMBI 24000 | C5: TODDYNHO
A6: OPERADOR MULTIFUNCIONAL | B6: COMBI 24000 | C6: TODDYNHO
A7: ANALISTA CONTROLADORIA PL | B7: CONTR FABR ITU MOH
A8: CWBEM | B8: =Tabela25[[#This Row],[CARGO]] -> CWBEM | C8: =Tabela25[[#This Row],[CARGO]] -> CWBEM
A9: ASSISTENTE LOGISTICA SR | B9: EXP E ARMAZENS FOODS | C9: EXPEDIÇÃO
A10: GERENTE DISTRIBUICAO | B10: EXP E ARMAZENS FOODS | C10: EXPEDIÇÃO
A11: SUPERVISOR DE DISTRIBUICAO A | B11: EXP E ARMAZENS FOODS | C11: EXPEDIÇÃO
A12: ANALISTA DE PCM PL | B12: GERENCIA MANUTENCAO | C12: MANUTENÇÃO
A13: COORDENADOR DE UTILIDADES | B13: GERENCIA MANUTENCAO | C13: MANUTENÇÃO
A14: ENGENHEIRO PL | B14: GERENCIA MANUTENCAO | C14: MANUTENÇÃO
A15: GERENTE MANUTENCAO | B15: GERENCIA MANUTENCAO | C15: MANUTENÇÃO
A16: TECNICO ELETROMECANICO II | B16: GERENCIA MANUTENCAO | C16: MANUTENÇÃO
A17: TECNICO ESPECIALISTA | B17: GERENCIA MANUTENCAO | C17: MANUTENÇÃO
A18: TECNICO MECANICO II | B18: GERENCIA MANUTENCAO | C18: MANUTENÇÃO
A19: TECNICO MECANICO III | B19: GERENCIA MANUTENCAO | C19: MANUTENÇÃO
A20: GERENTE DE MANUFATURA | B20: GERENCIA PRODUCAO BA
A21: OPERADOR MULTIFUNCIONAL ESPECIALIZADO | B21: GERENCIA PRODUCAO BA
A22: GERENTE DE MANUFATURA | B22: GERENTE DE PLANTA BA
A23: LIMGER | B23: =Tabela25[[#This Row],[CARGO]] -> LIMGER | C23: =Tabela25[[#This Row],[CARGO]] -> LIMGER
A24: MANPOWER | B24: =Tabela25[[#This Row],[CARGO]] -> MANPOWER | C24: =Tabela25[[#This Row],[CARGO]] -> MANPOWER
A25: OPERADOR UTILIDADES | B25: MANUTENCAO UTILIDADE | C25: MANUTENÇÃO
A26: AUXILIAR DE PRODUCAO | B26: PREPARACAO ESTERELIZ | C26: TODDYNHO
A27: OPERADOR MULTIFUNCIONAL | B27: PREPARACAO ESTERELIZ | C27: TODDYNHO
A28: OPERADOR MULTIFUNCIONAL ESPECIALIZADO | B28: PREPARACAO ESTERELIZ | C28: TODDYNHO
A29: AUXILIAR DE PRODUCAO | B29: PRODUCAO MAGICO BA | C29: TODDYNHO
A30: OPERADOR MULTIFUNCIONAL | B30: PRODUCAO MAGICO BA | C30: TODDYNHO
A31: AUXILIAR DE PRODUCAO | B31: PRODUCAO MISTURA BA | C31: TODDYNHO
A32: OPERADOR MULTIFUNCIONAL | B32: PRODUCAO MISTURA BA | C32: TODDY
A33: AUXILIAR DE PRODUCAO | B33: PRODUCAO TODDY BA | C33: TODDY
A34: OPERADOR MULTIFUNCIONAL | B34: PRODUCAO TODDY BA | C34: TODDY
A35: ANALISTA DE QUALIDADE JR | B35: QUALIDADE CHOCOLATE | C35: QUALIDADE
A36: COORDENADOR DE QUALIDADE | B36: QUALIDADE CHOCOLATE | C36: QUALIDADE
... A40: TECNICO SEGURANCA DO TRABALHO II | B40: SEG TRAB ENFERMAGEM | C40: EHS

Sheet INATIVOS
A1: GPID | B1: NOME | C1: EMPRESA | D1: DATA ADMISSÃO | E1: DATA SAIDA DO FRETADO | F1: MOTIVO | G1: LOGRADOURO | H1: Nº | I1: BAIRRO | J1: CIDADE | K1: TURNO | L1: PONTO DE EMBARQUE | M1: REFERÊNCIA | N1: TELEFONE
A2: 80228814 | B2: BRUNA MORENO DA SILVA | C2: PEPSICO | D2: N | E2: 44196 | F2: DESLIGAMENTO | G2: VIA PEDESTRE 47 | H2: 63 | I2: VIVEIROS | J2: FEIRA DE SANTANA | K2: 1º | M2: EM FRENTE A IGREJA QUADRANGULAR | N2: N
A3: 40177280 | B3: MONICA SANTANA SANTOS RODRIGUES | C3: PEPSICO | D3: N | E3: 44773 | F3: DESLIGAMENTO | G3: ESTRADA DO FRANCÊS | H3: 300 | I3: PAPAGAIO | J3: FEIRA DE SANTANA | K3: ADM | L3: COND: RESIDENCIAL NOVITÁ | N3: N
A4: 40257896 | B4: IZAEL DOS SANTOS FERREIRA | C4: PEPSICO | D4: N | E4: 44774 | F4: DESLIGAMENTO | G4: AV. GETULIO VARGAS | H4: N | I4: CONCEIÇÃO DO JACUIPE | J4: CONCEIÇÃO DO JACUIPE | K4: 2º | M4: EM FRENTE AO HOSPITAL ACM | N4: N
A5: 80013703 | B5: TIAGO MENEZES CONCEIÇÃO ANCHIETA | C5: PEPSICO | D5: N | E5: 44866 | F5: DESLIGAMENTO | G5: RUA SANTO AMARO | H5: 266 | I5: CHACARA SÃO COSME | J5: FEIRA DE SANTANA | K5: 1º | L5: EM FRENTE AO ASSISTENCIAL CHÁCARA SÃO COSME | N5: N
A6: 40286072 | B6: EVILÁSIO NELSON CORREIA CARVALHO JUNIOR | C6: PEPSICO | D6: N | E6: 44872 | F6: DESLIGAMENTO | G6: RUA ANTONIO FERNANDEZ DE OLIVEIRA | H6: 85 | I6: SÃO GONÇALO DOS CAMPOS | J6: SÃO GONÇALO DOS CAMPOS | K6: 1º | M6: PROX: A PADARIA (ART & PÃO) | N6: N
A7: 40201920 | B7: ELIENE CERQUEIRA DO CARMO | C7: PEPSICO | D7: N | E7: 44907 | F7: MUDANÇA PARA ROTEIRO ANTIGO | G7: JOÃO DURVAL | H7: N | I7: CENTRO | J7: FEIRA DE SANTANA | K7: ADM | M7: EM FRENTE A CASTELLE KIDS | N7: N
A8: 40216113 | B8: CASSIO MARTINS DA SILVA | C8: PEPSICO | D8: 10/06/2013 | E8: 44908 | F8: DESLIGAMENTO | G8: RUA POLITEAMA | H8: N | I8: SÚBAE | J8: FEIRA DE SANTANA | K8: 1º | M8: EM FRENTE AO COND FONTE DAS AGUÁS ( PROX A UNEF ) | N8: N
A9: 40201094 | B9: FABRICIO CARVALHO DE JESUS MAGALHÃES | C9: PEPSICO | D9: 22/08/2012 | E9: 44908 | F9: DESLIGAMENTO | G9: RUA VISCONDE DE MAUA | H9: N | I9: ESTAÇÃO NOVA | J9: FEIRA DE SANTANA | K9: 1º | M9: EM FRENTE AO SUPERMECADO MERCANTIL ORIENTE | N9: N
A10: NA | B10: JAMILE PEREIRA | C10: CWBEM | D10: N | E10: 44928 | F10: DESLIGAMENTO | G10: AVENIDA JOÃO DURVAL | H10: N | I10: BRASILIA | J10: FEIRA DE SANTANA | K10: ADM | M10: EM FRENTE A PETHORSE RAÇÕES | N10: N
A11: NA | B11: MAIARA ARGOLO NEGROMONTE | C11: RANDSTAD | D11: N | E11: 44937 | F11: DESLIGAMENTO | G11: RUA TUIUTI | H11: 270 | I11: CONCEIÇÃO | J11: FEIRA DE SANTANA | K11: 2º | N11: (75)9-9263-0006
A12: NA | B12: ELIAS BATISTA DOS SANTOS | C12: PEPSICO | E12: 44938 | F12: SEM COBERTURA DE BAIRRO | G12: RUA AV. FROTA | I12: MURILO LEITE | J12: SÃO GONÇALO | K12: ADM | L12: CLINICA DE MOTO | N12: N
A13: 80107261 | B13: VINICIUS SOUZA CORDEIRO | C13: PEPSICO | D13: 19/03/2018 | E13: 44958 | F13: MUDANÇA PARA VT | G13: RUA E 1 | H13: 7 | I13: FEIRA X | J13: FEIRA DE SANTANA | K13: ADM | M13: ESCOLA MANOEL GREGORIO | N13: N
A14: 80159517 | B14: DAIANE SILVA XAVIER | C14: PEPSICO | D14: 17/12/2018 | E14: 44958 | F14: MUDANÇA PARA VT | G14: RUA CAMBORIU | H14: 50 | I14: SIM | J14: FEIRA DE SANTANA | K14: ADM | L14: EM FRENTE CONCESSIONARIA CHERY, ATRÁS SHOPPIN AVENIDA | N14: N
A15: 40262398 | B15: LARISSA MAGALHAES DOREA MARTINS | C15: PEPSICO | D15: 17/03/2014 | E15: 44958 | F15: MUDANÇA PARA VT | G15: RUA CAJUEIRO | H15: 18 | I15: CONCEIÇÃO | J15: FEIRA DE SANTANA | K15: ADM | N15: N
A16: 40296432 | B16: ANNA RUBIA LOBO FERREIRA GOMES | C16: PEPSICO | D16: 04/05/2015 | E16: 44958 | F16: MUDANÇA PARA VT | G16: RUA TEREZINHA MAGALHÃES | H16: N | I16: FRATERNIDADE | J16: FEIRA DE SANTANA | K16: ADM | M16: EM FRENTE BAR DA KAISER | N16: N
A17: 40286567 | B17: SILVIO ROBSON AMARAL DOS SANTOS | C17: PEPSICO | D17: 03/11/2014 | E17: 44963 | F17: DESLIGAMENTO | G17: RUA COCOROBÓ | H17: 82 | I17: MANGABEIRA | J17: FEIRA DE SANTANA | K17: 1º | M17: PROX: AO COND: IGUATEMI 03 | N17: N
A18: 80155954 | B18: THAIS LIMA DOS SANTOS | C18: PEPSICO | D18: 19/11/2018 | E18: 44963 | F18: DESLIGAMENTO | G18: RUA RIO GRANDE | H18: 29 | I18: QUEIMADINHA | J18: FEIRA DE SANTANA | K18: 1º | L18: PONTO DE APANHA EM FRENTE AO POSTO DE SAÚDE | N18: N
A19: 80321032 | B19: JOELMA COSTA DA CRUZ NASCIMENTO | C19: PEPSICO | D19: 15/03/2021 | E19: 44963 | F19: DESLIGAMENTO | G19: RUA QUIRINÓPOLIS | H19: 259 | I19: BRASILIA | J19: FEIRA DE SANTANA | K19: 1º | M19: EM FRENTE A LOJA TURMA SARA | N19: N
A20: NA | B20: EDNEI CARDOSO DE OLIVEIRA | C20: RANDSTAD | D20: N | E20: 44967 | F20: DESLIGAMENTO | G20: RUA MINAS AZUIS | H20: 40 | I20: TOMBA | J20: FEIRA DE SANTANA | K20: 1º | L20: ESCOLA EDUCANDÁRIO UNIÃO DA VITORIA | N20: 9 8156 - 03001
A21: NA | B21: ALISSON SANTOS BARRETO | C21: RANDSTAD | D21: N | E21: 44972 | F21: DESLIGAMENTO | G21: RUA SÃO ROQUE | H21: 1853 | I21: PARQUE JETULIO | J21: FEIRA DE SANTANA | K21: AMD EPC | M21: REF: POSTO MENOR PREÇO | N21: (75)9-8839-9220
A22: NA | B22: LUIS CARLOS DOS SANTOS DE JESUS | C22: RANDSTAD | D22: N | E22: 44972 | F22: DESLIGAMENTO | G22: RUA SÃO FRANCISCO | H22: 20 | I22: FEIRA VII | J22: FEIRA DE SANTANA | K22: 1º | M22: CONJ HILDES FERREIRA | N22: (75)9 -8819 - 1825
A23: NA | B23: ROMARIO ARAUJO SANTANA | C23: RANDSTAD | D23: N | E23: 44972 | F23: DESLIGAMENTO | G23: RUA DESEMBARGADOR FILINTO BASTO | H23: 23 | I23: CENTRO | J23: FEIRA DE SANTANA | K23: AMD EPC | M23: PROX: A PADARIA PADRE OVIDIO | N23: N
A24: 40185180 | B24: PAULO HENRIQUE CORREIA OLIVEIRA | C24: PEPSICO | D24: 16/01/2012 | E24: 44972 | F24: DESLIGAMENTO | G24: RUA ITAPETINGA | H24: 471 | I24: SIM | J24: FEIRA DE SANTANA | K24: 3º | M24: PROX: A IGREJA, REF: COND: RESERVA REAL | N24: N
A25: NA | B25: AURINO AMORIM RODRIGUES | C25: GRI | D25: N | E25: 44981 | F25: DESLIGAMENTO | G25: RUA SALGADEIRA | H25: N | I25: HUMILDES | J25: FEIRA DE SANTANA | K25: ADM | L25: EM FRENTE A LOJA DE MOVEIS DEUS É FIEL | N25: N
A26: NA | B26: EZEQUIEL LIMA DOS SANTOS | C26: GRI | D26: N | E26: 44981 | F26: DESLIGAMENTO | G26: RUA S | H26: N | I26: AVIARIO | J26: FEIRA DE SANTANA | K26: 1º | L26: EM FRENTE AO MERCADINHO COSME E DAMIÃO | N26: (75)9-8240-6561
A27: NA | B27: ISABELLA DOS SANTOS DE OLIVEIRA | C27: GRI | D27: N | E27: 44981 | F27: DESLIGAMENTO | G27: RUA LOUDES MARIA DA SILVA | H27: N | I27: MANGABEIRA | J27: FEIRA DE SANTANA | K27: ADM | N27: N
A28: NA | B28: JOSÉ RAMOS DOS SANTOS | C28: GRI | D28: N | E28: 44981 | F28: DESLIGAMENTO | G28: RUA MILTON486 | H28: N | I28: AMELIA RODRIGUES (ITAPICURU) | J28: AMELIA RODRIGUES (ITAPICURU) | K28: ADM | L28: ATRÁS DO FORUM DE A. RODRIGUES | N28: N
A29: NA | B29: MARIVAN NASCIMENTO | C29: GRI | D29: N | E29: 44981 | F29: DESLIGAMENTO | G29: RUA RIO ITAPEMIRIM | H29: N | I29: BRASILIA | J29: FEIRA DE SANTANA | K29: 2º | L29: EM FRENTE A DROGARIA DO BAIRRO | N29: N
A30: 40296432 | B30: ANNA RUBIA LOBO FERREIRA GOMES | C30: PEPSICO | D30: 04/05/2015 | E30: 44984 | F30: FALECIMENTO | G30: RUA TEREZINHA MAGALHÃES | H30: N | I30: FRATERNIDADE | J30: FEIRA DE SANTANA | K30: 2º | M30: EM FRENTE BAR DA KAISER | N30: N
A31: NA | B31: MARCELA BARBARA PEREIRA DE JESUS | C31: CWBEM | D31: N | E31: 44998 | F31: DESLIGAMENTO | G31: RUA SÃO PEDRO DOS DERROS | H31: 7 | I31: SIM | J31: FEIRA DE SANTANA | K31: ADM | N31: 9 8142 - 7843
A32: NA | B32: ELAINE DA CRUZ COSTA BARBOSA | C32: RANDSTAD | D32: N | E32: 44998 | F32: DESLIGAMENTO | G32: QUINTA DO SOL VILLE 1 | H32: N | I32: PARQUE IPÊ | J32: FEIRA DE SANTANA | K32: AMD EPC | N32: (75)9-9204 -2511
A33: NA | B33: ZOENE DE JESUS | C33: RANDSTAD | D33: N | E33: 44998 | F33: DESLIGAMENTO | G33: RUA HONORATO BONFIM | H33: 635 | I33: BRASILIA | J33: FEIRA DE SANTANA | K33: 2º | L33: RPOX: A IGREJA ASSEMBLEIA DE DEUS | N33: (75)9-8169 - 2968
A34: NA | B34: RICARDO DA SILVA SANTOS | C34: RANDSTAD | D34: N | E34: 44998 | F34: DESLIGAMENTO | G34: RUA RIO VERMELHO | H34: 755 | I34: SANTA MONICA | J34: FEIRA DE SANTANA | K34: 2º | L34: FUNDO DO POSTO CAJUEIRO | N34: (75)9-8152-7047
A35: .09366917 | B35: SONIA MARIA DE CARVALHO SOUZA | C35: MANPOWER | D35: 44756 | E35: 45019 | F35: DESLIGAMENTO | G35: RUA ARI BARROSO | H35: 334 | I35: SERRARIA BRASIL | J35: FEIRA DE SANTANA | K35: ADM | M35: REF: RODOVIARIA | N35: N
A36: 80152714 | B36: MARLUCIA DA CONCEIÇÃO LIMA | C36: PEPSICO | D36: 05/11/2018 | E36: 45021 | F36: DESLIGAMENTO | G36: RUA OPALA | H36: 46 | I36: BRASILIA | J36: FEIRA DE SANTANA | K36: 2º | L36: EM FRENTE MERCADINHO NOGUEIRA 2 | N36: N
A37: 80101499 | B37: ELANE SANTANA | C37: PEPSICO | D37: 12/02/2018 | E37: 45028 | F37: DESLIGAMENTO | G37: RESIDENCIAL ALTO DO ROSARIO BL | H37: 18 | I37: MANGABEIRA | J37: FEIRA DE SANTANA | K37: 2º
A38: 40287198 | B38: GILHERLON OLIVEIRA DE JESUS | C38: PEPSICO | D38: 01/12/2014 | E38: 45028 | F38: DESLIGAMENTO | G38: RUA MARIO PEREIRA FRANCO | H38: 97 | I38: SOBRADINHO | J38: FEIRA DE SANTANA | K38: 1º
A39: 80069244 | B39: CAILAN SILVA BARROS | C39: PEPSICO | D39: 17/07/2017 | E39: 45029 | F39: DESLIGAMENTO | G39: RUA CAMILO V COSTA | H39: N | I39: PAPAGAIO | J39: FEIRA DE SANTANA | K39: 2º | M39: EM FRENTE AO COND VILLE DUO
A40: 40185185 | B40: DENILLY SOUZA ALVES | C40: PEPSICO | D40: 16/01/2012 | E40: 45033 | F40: DESLIGAMENTO | G40: RUA MEDEIROS NETO | H40: N | I40: TOMBA | J40: FEIRA DE SANTANA | K40: ADM | M40: EM FRENTE AO COND: PARQUE DAS FILIPINAS | N40: N
...

Sheet MOTORISTAS
B2: MOTORISTAS
B3: MOTORISTA | C3: CNH | D3: DATA EXP. | E3: DATA VAL. | F3: EXAME TOXICOLÓGICO | G3: CURSO DETRAN | H3: DOCUMENTO ASO
B4: HUDSON BARBOSA DE ARAUJO PEREIRA | C4: 3014420403 | D4: 37854 | E4: 45986 | F4: 45965 | G4: EAR | H4: OK
B5: OSMAN MIRANDA DA CRUZ | C5: 2182335135 | D5: 32569 | E5: 45978 | F5: 45943 | G5: EAR | H5: OK
B6: SIDNEY MIRANDA OLIVEIRA | C6: 3918018860 | D6: 44930 | E6: 48568 | F6: 45840 | G6: EAR | H6: OK
B7: LIDIVAL DIAS FREITAS | C7: 2623670313 | D7: 44838 | E7: 46635 | F7: 45748 | G7: EAR | H7: OK
B8: EDNALDO DO CARMO LOPES | C8: 1599930667 | D8: 44470 | E8: 48099 | F8: 45798 | G8: EAR | H8: N/A
B9: OTAVIO OLIVEIRA DO VALE | C9: 3958218521 | D9: 44494 | E9: 48124 | F9: 46134 | G9: EAR | H9: N/A
B10: ANGELO MARIO DOS SANTOS | C10: 4753813680 | D10: 44848 | E10: 48497 | F10: 45930 | G10: EAR | H10: N/A
B11: ROQUE DE JESUS ALMEIDA | C11: 1680405910 | D11: 44312 | E11: 45971 | F11: 45996 | G11: EAR | H11: N/A
B12: SANDRO JOSE FERREIRA DE FREITAS | C12: 4235721929 | D12: 42783 | E12: 45998 | F12: 46198 | G12: EAR | H12: N/A
B13: WALMIR DA CONCEIÇÃO RIBEIRO | C13: 593945360 | D13: 44875 | E13: 46700 | F13: 46196 | G13: EAR | H13: N/A
B14: GENIVALDO DE LIMA DE JESUS | C14: 4640872562 | D14: 39945 | E14: 47995 | F14: 46267 | G14: EAR | H14: N/A
B15: BRUNNO ANDERSON DA SILVA LEAL | C15: 882951029 | D15: 45589 | E15: 49202 | F15: 46196 | G15: EAR | H15: N/A
B16: SIDNEY ALVES DOS SANTOS | C16: 5465086442 | D16: 45345 | E16: 45986 | F16: N/A | G16: N/A | H16: N/A
B17: JOÃO EVANGELISTA RIBEIRO MORAIS | C17: 1417930017 | D17: 45202 | E17: 46291 | F17: N/A | G17: N/A | H17: N/A
B18: HUMBERTO SAMPAIO DE MACEDO | C18: 4962815875 | D18: 31596 | E18: 45886 | F18: N/A | G18: N/A | H18: N/A
B19: IANEY SANTOS MOREIRA | C19: 3398002008 | D19: 38094 | E19: 49087 | F19: N/A | G19: N/A | H19: N/A
B20: JOÃO VICTOR MATOS SILVA | C20: 7567858820 | D20: 45863 | E20: 45862 | F20: N/A | G20: N/A | H20: N/A
B21: JUCELIA SANTOS DA SILVA | C21: 2583278938 | D21: 44770 | E21: 46593 | F21: N/A | G21: N/A | H21: N/A
B22: UBIRAJARA FRANÇA | C22: 1179007984 | D22: 45043 | E22: 46826 | F22: N/A | G22: N/A | H22: N/A
B23: JADSON BORGES DA SILVA SANTOS | C23: 4549270300 | D23: 44671 | E23: 48303 | F23: N/A | G23: N/A | H23: N/A
B24: ANTONIO PAULO DA SILVA | C24: 5076466597 | D24: 44460 | E24: 46279 | F24: N/A | G24: N/A | H24: N/A
B25: HENRIQUE MENDES DA SILVA | C25: 2302730187 | D25: 44763 | E25: 46588 | F25: N/A | G25: N/A | H25: N/A
B26: FABIANO SILVA DE JESUS | C26: 5526518246 | D26: 45287 | E26: 48918 | F26: N/A | G26: N/A | H26: N/A

Sheet VEÍCULOS
B2: VEÍCULOS
B3: PLACA | C3: DOCUMENTO VEICULO (CRLV) | D3: LICENCIADO | E3: DATA VALIDADE | F3: CONOTACOGRAFO
B4: SKB4C99 | C4: 244079612187 | D4: 2025 | E4: 45961 | F4: 0011065641
B5: SKE6J24 | C5: 244110292140 | D5: 2025 | E5: 45961 | F5: 0011154537
B6: SKG2H53 | C6: 244145005511 | D6: 2025 | E6: 45961 | F6: P23488955
B7: SKG3F12 | C7: 244145004680 | D7: 2025 | E7: 45961 | F7: P23427834
B8: SKG4G65 | C8: 244139120290 | D8: 2025 | E8: 45961 | F8: P23471388
B9: SKG4J37 | C9: 244145006186 | D9: 2025 | E9: 45961 | F9: P23489735
B10: QTW6B54 | C10: 01218946501 | D10: 2025 | E10: 45900 | F10: P23489273
B11: NZI6F44 | C11: 233697016830 | D11: 2025 | E11: 45869 | F11: P23466564
B12: PJW3313 | C12: 01083690873 | D12: 2025 | E12: 31/02/2025 | F12: 0010770653
B13: OLF0D24 | C13: 213197176260 | D13: 2025 | E13: 31/06/2025 | F13: 0010061759
B14: PKS1I39 | C14: 213148020812 | D14: 2025 | E14: 45900 | F14: N/A
B15: OZR7B70 | C15: 223391674806 | D15: 2025 | E15: 31/09/2025 | F15: N/A
B16: PLS1E39 | C16: 223498874322 | D16: 2025 | E16: 45900 | F16: N/A
B17: PJO3A80 | C17: 244004094984 | D17: 2025 | E17: 45808 | F17: N/A
B18: SKJ7D62 | C18: 244181377660 | D18: 2025 | E18: 45930 | F18: N/A
B19: OLD1G02 | C19: 223564347941 | D19: 2025 | E19: 45899 | F19: N/A
B20: PBK8F68 | C20: 233891694377 | D20: 2025 | E20: 30/02/2025 | F20: N/A
B21: OZV7973 | C21: 243961457786 | D21: 2024 | E21: 45898 | F21: N/A

Sheet VEICULOS E MOTORISTAS ATIVOS
B2: VEÍCULO | C2: MOTORISTAS ATUAIS ROTEIROS PEPSICO | D2: CNH | E2: TOXICOLÓGICO | F2: CURSO DETRAN | G2: ASO | H2: ROTA | I2: TURNO
B3: OZV7973 | C3: JADSON BORGES DA SILVA SANTOS | D3: 4549270300 | E3: N/A | F3: N/A | G3: N/A | H3: 1 | I3: 1° | K3: QUANTIDADE DE MOTORISTAS
B4: OZR7B70 | C4: BRUNNO ANDERSON DA SILVA LEAL | D4: 882951029 | E4: 46196 | F4: EAR | G4: N/A | H4: 1 | I4: 1° | K4: 1 TURNO | L4: 2 TURNO | M4: 3 TURNO | N4: ADM
B5: RDI2F74 | C5: ANTONIO PAULO DA SILVA | D5: 5076466597 | E5: N/A | F5: N/A | G5: N/A | H5: 2 | I5: 1° | K5: 14 | L5: 10 | M5: 5 | N5: 3
B6: SKB4C99 | C6: HUDSON BARBOSA DE ARAUJO PEREIRA | D6: 3014420403 | E6: N/A | F6: N/A | G6: OK | H6: 3 | I6: 1° | M6: TOTAL= | N6: =SUM(K5:N5) -> 32
B7: OLF0D24 | C7: WALMIR DA CONCEIÇÃO RIBEIRO | D7: 593945360 | E7: 46196 | F7: EAR | G7: N/A | H7: 4 | I7: 1°
B8: SKE6J24 | C8: OSMAN MIRANDA DA CRUZ | D8: 2182335135 | E8: N/A | F8: N/A | G8: OK | H8: 5 | I8: 1°
B9: PSF8G68 | C9: EDNALDO DO CARMO LOPES | D9: 1599930667 | E9: 45798 | F9: EAR | G9: N/A | H9: 5 | I9: 1°
B10: SKG2H53 | C10: LIDIVAL DIAS FREITAS | D10: 2623670313 | E10: N/A | F10: N/A | G10: OK | H10: 6 | I10: 1°
B11: OXU9218 | C11: ANGELO MARIO DOS SANTOS | D11: 4753813680 | E11: 45930 | F11: EAR | G11: N/A | H11: 6 | I11: 1°
B12: OZR7B70 | C12: JOÃO EVANGELISTA RIBEIRO MORAIS | D12: 1417930017 | E12: N/A | F12: N/A | G12: N/A | H12: 7 | I12: 1°
B13: SKG3F12 | C13: SIDNEY MIRANDA OLIVEIRA | D13: 3918018860 | E13: N/A | F13: N/A | G13: OK | H13: 8 | I13: 1°
B14: KRR9A92 | C14: FABIANO SILVA DE JESUS | D14: 5526518246 | E14: N/A | F14: N/A | G14: N/A | H14: 8 | I14: 1°
B15: PKS1I39 | C15: SIDNEY ALVES DOS SANTOS | D15: 5465086442 | E15: N/A | F15: N/A | G15: N/A | H15: 9 | I15: 1°
B16: PLS1E39 | C16: HUMBERTO SAMPAIO DE MACEDO | D16: 4962815875 | E16: N/A | F16: N/A | G16: N/A | H16: 9 | I16: 1°
B17: QTW6C71 | C17: HENRIQUE MENDES DA SILVA | D17: 2302730187 | E17: N/A | F17: N/A | G17: N/A | H17: 1 | I17: ADM
B18: OLD1G02 | C18: JUCELIA SANTOS DA SILVA | D18: 2583278938 | E18: N/A | F18: N/A | G18: N/A | H18: 2 | I18: ADM
B19: OZR7B70 | C19: JOÃO EVANGELISTA RIBEIRO MORAIS | D19: 1417930017 | E19: N/A | F19: N/A | G19: N/A | H19: 3 | I19: ADM
B20: QTW6B54 | C20: SANDRO JOSE FERREIRA DE FREITAS | D20: 4235721929 | E20: 46198 | F20: EAR | G20: N/A | H20: 1 | I20: 2°
B21: PJO3A80 | C21: IANEY SANTOS MOREIRA | D21: 3398002008 | E21: N/A | F21: N/A | G21: N/A | H21: 1 | I21: 2°
B22: SKJ7D62 | C22: JOÃO VICTOR MATOS SILVA | D22: 7567858820 | E22: N/A | F22: N/A | G22: NA/ | H22: 1 | I22: 2°
B23: PXO7I32 | C23: ROQUE DE JESUS ALMEIDA | D23: 1680405910 | E23: 45996 | F23: EAR | G23: N/A | H23: 2 | I23: 2°
